2023-08-28 22:53:35 [INFO] Configured app logging, linked to file:
./logs/log1.log

2023-08-28 22:53:36 [INFO] Configured app logging, linked to file:
./logs/log1.log

2023-08-29 00:20:35 [ERROR] Failed to delete user
Traceback (most recent call last):
  File "/home/sale/projects/coursework/iep_project/store_management_system/development/user_management_system/authentication_service/app/blueprints/delete.py", line 50, in delete_user
    user = User.filter_by(email=data['email']) \
AttributeError: type object 'User' has no attribute 'filter_by'
2023-08-29 00:20:35 [ERROR] Failed to delete user
Traceback (most recent call last):
  File "/home/sale/projects/coursework/iep_project/store_management_system/development/user_management_system/authentication_service/app/blueprints/delete.py", line 50, in delete_user
    user = User.filter_by(email=data['email']) \
AttributeError: type object 'User' has no attribute 'filter_by'
2023-08-29 00:20:35 [ERROR] Failed to delete user
Traceback (most recent call last):
  File "/home/sale/projects/coursework/iep_project/store_management_system/development/user_management_system/authentication_service/app/blueprints/delete.py", line 50, in delete_user
    user = User.filter_by(email=data['email']) \
AttributeError: type object 'User' has no attribute 'filter_by'
2023-08-29 00:20:35 [ERROR] Failed to delete user
Traceback (most recent call last):
  File "/home/sale/projects/coursework/iep_project/store_management_system/development/user_management_system/authentication_service/app/blueprints/delete.py", line 50, in delete_user
    user = User.filter_by(email=data['email']) \
AttributeError: type object 'User' has no attribute 'filter_by'
2023-08-29 00:21:56 [ERROR] Failed to register customer
Traceback (most recent call last):
  File "/home/sale/projects/coursework/iep_project/store_management_system/development/user_management_system/authentication_service/app/blueprints/register.py", line 100, in register_user_view
    raise e
  File "/home/sale/projects/coursework/iep_project/store_management_system/development/user_management_system/authentication_service/app/blueprints/register.py", line 94, in register_user_view
    has_role = HasRole(user_id=user.id, role_id=role.id)
AttributeError: 'NoneType' object has no attribute 'id'
2023-08-29 00:21:56 [ERROR] Failed to register courier
Traceback (most recent call last):
  File "/home/sale/projects/coursework/iep_project/store_management_system/development/user_management_system/authentication_service/app/blueprints/register.py", line 100, in register_user_view
    raise e
  File "/home/sale/projects/coursework/iep_project/store_management_system/development/user_management_system/authentication_service/app/blueprints/register.py", line 94, in register_user_view
    has_role = HasRole(user_id=user.id, role_id=role.id)
AttributeError: 'NoneType' object has no attribute 'id'
2023-08-29 00:21:56 [ERROR] Failed to register courier
Traceback (most recent call last):
  File "/home/sale/projects/coursework/iep_project/store_management_system/development/user_management_system/authentication_service/app/blueprints/register.py", line 100, in register_user_view
    raise e
  File "/home/sale/projects/coursework/iep_project/store_management_system/development/user_management_system/authentication_service/app/blueprints/register.py", line 94, in register_user_view
    has_role = HasRole(user_id=user.id, role_id=role.id)
AttributeError: 'NoneType' object has no attribute 'id'
2023-08-29 00:21:56 [ERROR] Failed to register customer
Traceback (most recent call last):
  File "/home/sale/projects/coursework/iep_project/store_management_system/development/user_management_system/authentication_service/app/blueprints/register.py", line 100, in register_user_view
    raise e
  File "/home/sale/projects/coursework/iep_project/store_management_system/development/user_management_system/authentication_service/app/blueprints/register.py", line 94, in register_user_view
    has_role = HasRole(user_id=user.id, role_id=role.id)
AttributeError: 'NoneType' object has no attribute 'id'
2023-08-29 00:21:56 [ERROR] Failed to register courier
Traceback (most recent call last):
  File "/home/sale/projects/coursework/iep_project/store_management_system/development/user_management_system/authentication_service/app/blueprints/register.py", line 100, in register_user_view
    raise e
  File "/home/sale/projects/coursework/iep_project/store_management_system/development/user_management_system/authentication_service/app/blueprints/register.py", line 94, in register_user_view
    has_role = HasRole(user_id=user.id, role_id=role.id)
AttributeError: 'NoneType' object has no attribute 'id'
2023-08-29 00:21:57 [ERROR] Failed to register customer
Traceback (most recent call last):
  File "/home/sale/projects/coursework/iep_project/store_management_system/development/user_management_system/authentication_service/app/blueprints/register.py", line 100, in register_user_view
    raise e
  File "/home/sale/projects/coursework/iep_project/store_management_system/development/user_management_system/authentication_service/app/blueprints/register.py", line 94, in register_user_view
    has_role = HasRole(user_id=user.id, role_id=role.id)
AttributeError: 'NoneType' object has no attribute 'id'
2023-08-29 00:22:30 [ERROR] Failed to register customer
Traceback (most recent call last):
  File "/home/sale/projects/coursework/iep_project/store_management_system/development/user_management_system/authentication_service/app/blueprints/register.py", line 100, in register_user_view
    raise e
  File "/home/sale/projects/coursework/iep_project/store_management_system/development/user_management_system/authentication_service/app/blueprints/register.py", line 94, in register_user_view
    has_role = HasRole(user_id=user.id, role_id=role.id)
AttributeError: 'NoneType' object has no attribute 'id'
2023-08-29 00:22:31 [ERROR] Failed to register courier
Traceback (most recent call last):
  File "/home/sale/projects/coursework/iep_project/store_management_system/development/user_management_system/authentication_service/app/blueprints/register.py", line 100, in register_user_view
    raise e
  File "/home/sale/projects/coursework/iep_project/store_management_system/development/user_management_system/authentication_service/app/blueprints/register.py", line 94, in register_user_view
    has_role = HasRole(user_id=user.id, role_id=role.id)
AttributeError: 'NoneType' object has no attribute 'id'
2023-08-29 00:22:31 [ERROR] Failed to register courier
Traceback (most recent call last):
  File "/home/sale/projects/coursework/iep_project/store_management_system/development/user_management_system/authentication_service/app/blueprints/register.py", line 100, in register_user_view
    raise e
  File "/home/sale/projects/coursework/iep_project/store_management_system/development/user_management_system/authentication_service/app/blueprints/register.py", line 94, in register_user_view
    has_role = HasRole(user_id=user.id, role_id=role.id)
AttributeError: 'NoneType' object has no attribute 'id'
2023-08-29 00:22:31 [ERROR] Failed to register customer
Traceback (most recent call last):
  File "/home/sale/projects/coursework/iep_project/store_management_system/development/user_management_system/authentication_service/app/blueprints/register.py", line 100, in register_user_view
    raise e
  File "/home/sale/projects/coursework/iep_project/store_management_system/development/user_management_system/authentication_service/app/blueprints/register.py", line 94, in register_user_view
    has_role = HasRole(user_id=user.id, role_id=role.id)
AttributeError: 'NoneType' object has no attribute 'id'
2023-08-29 00:22:31 [ERROR] Failed to register courier
Traceback (most recent call last):
  File "/home/sale/projects/coursework/iep_project/store_management_system/development/user_management_system/authentication_service/app/blueprints/register.py", line 100, in register_user_view
    raise e
  File "/home/sale/projects/coursework/iep_project/store_management_system/development/user_management_system/authentication_service/app/blueprints/register.py", line 94, in register_user_view
    has_role = HasRole(user_id=user.id, role_id=role.id)
AttributeError: 'NoneType' object has no attribute 'id'
2023-08-29 00:22:31 [ERROR] Failed to register customer
Traceback (most recent call last):
  File "/home/sale/projects/coursework/iep_project/store_management_system/development/user_management_system/authentication_service/app/blueprints/register.py", line 100, in register_user_view
    raise e
  File "/home/sale/projects/coursework/iep_project/store_management_system/development/user_management_system/authentication_service/app/blueprints/register.py", line 94, in register_user_view
    has_role = HasRole(user_id=user.id, role_id=role.id)
AttributeError: 'NoneType' object has no attribute 'id'
2023-08-29 00:23:47 [INFO] Configured app logging, linked to file:
./logs/log1.log

2023-08-29 00:24:13 [INFO] Configured app logging, linked to file:
./logs/log1.log

2023-08-29 00:24:14 [INFO] Configured app logging, linked to file:
./logs/log1.log

2023-08-29 00:24:25 [ERROR] Failed to register customer
Traceback (most recent call last):
  File "/home/sale/projects/coursework/iep_project/store_management_system/development/user_management_system/authentication_service/app/blueprints/register.py", line 100, in register_user_view
    raise e
  File "/home/sale/projects/coursework/iep_project/store_management_system/development/user_management_system/authentication_service/app/blueprints/register.py", line 94, in register_user_view
    has_role = HasRole(user_id=user.id, role_id=role.id)
AttributeError: 'NoneType' object has no attribute 'id'
2023-08-29 00:24:25 [ERROR] Failed to register courier
Traceback (most recent call last):
  File "/home/sale/projects/coursework/iep_project/store_management_system/development/user_management_system/authentication_service/app/blueprints/register.py", line 100, in register_user_view
    raise e
  File "/home/sale/projects/coursework/iep_project/store_management_system/development/user_management_system/authentication_service/app/blueprints/register.py", line 94, in register_user_view
    has_role = HasRole(user_id=user.id, role_id=role.id)
AttributeError: 'NoneType' object has no attribute 'id'
2023-08-29 00:24:25 [ERROR] Failed to register courier
Traceback (most recent call last):
  File "/home/sale/projects/coursework/iep_project/store_management_system/development/user_management_system/authentication_service/app/blueprints/register.py", line 100, in register_user_view
    raise e
  File "/home/sale/projects/coursework/iep_project/store_management_system/development/user_management_system/authentication_service/app/blueprints/register.py", line 94, in register_user_view
    has_role = HasRole(user_id=user.id, role_id=role.id)
AttributeError: 'NoneType' object has no attribute 'id'
2023-08-29 00:24:25 [ERROR] Failed to register customer
Traceback (most recent call last):
  File "/home/sale/projects/coursework/iep_project/store_management_system/development/user_management_system/authentication_service/app/blueprints/register.py", line 100, in register_user_view
    raise e
  File "/home/sale/projects/coursework/iep_project/store_management_system/development/user_management_system/authentication_service/app/blueprints/register.py", line 94, in register_user_view
    has_role = HasRole(user_id=user.id, role_id=role.id)
AttributeError: 'NoneType' object has no attribute 'id'
2023-08-29 00:24:25 [ERROR] Failed to register courier
Traceback (most recent call last):
  File "/home/sale/projects/coursework/iep_project/store_management_system/development/user_management_system/authentication_service/app/blueprints/register.py", line 100, in register_user_view
    raise e
  File "/home/sale/projects/coursework/iep_project/store_management_system/development/user_management_system/authentication_service/app/blueprints/register.py", line 94, in register_user_view
    has_role = HasRole(user_id=user.id, role_id=role.id)
AttributeError: 'NoneType' object has no attribute 'id'
2023-08-29 00:24:25 [ERROR] Failed to register customer
Traceback (most recent call last):
  File "/home/sale/projects/coursework/iep_project/store_management_system/development/user_management_system/authentication_service/app/blueprints/register.py", line 100, in register_user_view
    raise e
  File "/home/sale/projects/coursework/iep_project/store_management_system/development/user_management_system/authentication_service/app/blueprints/register.py", line 94, in register_user_view
    has_role = HasRole(user_id=user.id, role_id=role.id)
AttributeError: 'NoneType' object has no attribute 'id'
2023-08-29 00:34:28 [INFO] Configured app logging, linked to file:
./logs/log1.log

2023-08-29 00:34:29 [INFO] Configured app logging, linked to file:
./logs/log1.log

2023-08-29 12:21:54 [INFO] Configured app logging, linked to file:
./logs/log1.log

2023-08-29 12:21:55 [INFO] Configured app logging, linked to file:
./logs/log1.log

2023-08-29 14:13:00 [ERROR] Failed to register customer
Traceback (most recent call last):
  File "/home/sale/projects/coursework/iep_project/store_management_system/development/user_management_system/authentication_service/venv/lib/python3.10/site-packages/sqlalchemy/engine/base.py", line 1276, in _execute_context
    self.dialect.do_execute(
  File "/home/sale/projects/coursework/iep_project/store_management_system/development/user_management_system/authentication_service/venv/lib/python3.10/site-packages/sqlalchemy/engine/default.py", line 608, in do_execute
    cursor.execute(statement, parameters)
  File "/home/sale/projects/coursework/iep_project/store_management_system/development/user_management_system/authentication_service/venv/lib/python3.10/site-packages/pymysql/cursors.py", line 153, in execute
    result = self._query(query)
  File "/home/sale/projects/coursework/iep_project/store_management_system/development/user_management_system/authentication_service/venv/lib/python3.10/site-packages/pymysql/cursors.py", line 322, in _query
    conn.query(q)
  File "/home/sale/projects/coursework/iep_project/store_management_system/development/user_management_system/authentication_service/venv/lib/python3.10/site-packages/pymysql/connections.py", line 558, in query
    self._affected_rows = self._read_query_result(unbuffered=unbuffered)
  File "/home/sale/projects/coursework/iep_project/store_management_system/development/user_management_system/authentication_service/venv/lib/python3.10/site-packages/pymysql/connections.py", line 822, in _read_query_result
    result.read()
  File "/home/sale/projects/coursework/iep_project/store_management_system/development/user_management_system/authentication_service/venv/lib/python3.10/site-packages/pymysql/connections.py", line 1200, in read
    first_packet = self.connection._read_packet()
  File "/home/sale/projects/coursework/iep_project/store_management_system/development/user_management_system/authentication_service/venv/lib/python3.10/site-packages/pymysql/connections.py", line 772, in _read_packet
    packet.raise_for_error()
  File "/home/sale/projects/coursework/iep_project/store_management_system/development/user_management_system/authentication_service/venv/lib/python3.10/site-packages/pymysql/protocol.py", line 221, in raise_for_error
    err.raise_mysql_exception(self._data)
  File "/home/sale/projects/coursework/iep_project/store_management_system/development/user_management_system/authentication_service/venv/lib/python3.10/site-packages/pymysql/err.py", line 143, in raise_mysql_exception
    raise errorclass(errno, errval)
pymysql.err.OperationalError: (1049, "Unknown database 'authentication'")

The above exception was the direct cause of the following exception:

Traceback (most recent call last):
  File "/home/sale/projects/coursework/iep_project/store_management_system/development/user_management_system/authentication_service/app/blueprints/register.py", line 100, in register_user_view
    raise e
  File "/home/sale/projects/coursework/iep_project/store_management_system/development/user_management_system/authentication_service/app/blueprints/register.py", line 87, in register_user_view
    db.session.flush()
  File "/home/sale/projects/coursework/iep_project/store_management_system/development/user_management_system/authentication_service/venv/lib/python3.10/site-packages/sqlalchemy/orm/scoping.py", line 163, in do
    return getattr(self.registry(), name)(*args, **kwargs)
  File "/home/sale/projects/coursework/iep_project/store_management_system/development/user_management_system/authentication_service/venv/lib/python3.10/site-packages/sqlalchemy/orm/session.py", line 2540, in flush
    self._flush(objects)
  File "/home/sale/projects/coursework/iep_project/store_management_system/development/user_management_system/authentication_service/venv/lib/python3.10/site-packages/sqlalchemy/orm/session.py", line 2681, in _flush
    with util.safe_reraise():
  File "/home/sale/projects/coursework/iep_project/store_management_system/development/user_management_system/authentication_service/venv/lib/python3.10/site-packages/sqlalchemy/util/langhelpers.py", line 68, in __exit__
    compat.raise_(
  File "/home/sale/projects/coursework/iep_project/store_management_system/development/user_management_system/authentication_service/venv/lib/python3.10/site-packages/sqlalchemy/util/compat.py", line 182, in raise_
    raise exception
  File "/home/sale/projects/coursework/iep_project/store_management_system/development/user_management_system/authentication_service/venv/lib/python3.10/site-packages/sqlalchemy/orm/session.py", line 2642, in _flush
    flush_context.execute()
  File "/home/sale/projects/coursework/iep_project/store_management_system/development/user_management_system/authentication_service/venv/lib/python3.10/site-packages/sqlalchemy/orm/unitofwork.py", line 422, in execute
    rec.execute(self)
  File "/home/sale/projects/coursework/iep_project/store_management_system/development/user_management_system/authentication_service/venv/lib/python3.10/site-packages/sqlalchemy/orm/unitofwork.py", line 586, in execute
    persistence.save_obj(
  File "/home/sale/projects/coursework/iep_project/store_management_system/development/user_management_system/authentication_service/venv/lib/python3.10/site-packages/sqlalchemy/orm/persistence.py", line 239, in save_obj
    _emit_insert_statements(
  File "/home/sale/projects/coursework/iep_project/store_management_system/development/user_management_system/authentication_service/venv/lib/python3.10/site-packages/sqlalchemy/orm/persistence.py", line 1135, in _emit_insert_statements
    result = cached_connections[connection].execute(
  File "/home/sale/projects/coursework/iep_project/store_management_system/development/user_management_system/authentication_service/venv/lib/python3.10/site-packages/sqlalchemy/engine/base.py", line 1011, in execute
    return meth(self, multiparams, params)
  File "/home/sale/projects/coursework/iep_project/store_management_system/development/user_management_system/authentication_service/venv/lib/python3.10/site-packages/sqlalchemy/sql/elements.py", line 298, in _execute_on_connection
    return connection._execute_clauseelement(self, multiparams, params)
  File "/home/sale/projects/coursework/iep_project/store_management_system/development/user_management_system/authentication_service/venv/lib/python3.10/site-packages/sqlalchemy/engine/base.py", line 1124, in _execute_clauseelement
    ret = self._execute_context(
  File "/home/sale/projects/coursework/iep_project/store_management_system/development/user_management_system/authentication_service/venv/lib/python3.10/site-packages/sqlalchemy/engine/base.py", line 1316, in _execute_context
    self._handle_dbapi_exception(
  File "/home/sale/projects/coursework/iep_project/store_management_system/development/user_management_system/authentication_service/venv/lib/python3.10/site-packages/sqlalchemy/engine/base.py", line 1510, in _handle_dbapi_exception
    util.raise_(
  File "/home/sale/projects/coursework/iep_project/store_management_system/development/user_management_system/authentication_service/venv/lib/python3.10/site-packages/sqlalchemy/util/compat.py", line 182, in raise_
    raise exception
  File "/home/sale/projects/coursework/iep_project/store_management_system/development/user_management_system/authentication_service/venv/lib/python3.10/site-packages/sqlalchemy/engine/base.py", line 1276, in _execute_context
    self.dialect.do_execute(
  File "/home/sale/projects/coursework/iep_project/store_management_system/development/user_management_system/authentication_service/venv/lib/python3.10/site-packages/sqlalchemy/engine/default.py", line 608, in do_execute
    cursor.execute(statement, parameters)
  File "/home/sale/projects/coursework/iep_project/store_management_system/development/user_management_system/authentication_service/venv/lib/python3.10/site-packages/pymysql/cursors.py", line 153, in execute
    result = self._query(query)
  File "/home/sale/projects/coursework/iep_project/store_management_system/development/user_management_system/authentication_service/venv/lib/python3.10/site-packages/pymysql/cursors.py", line 322, in _query
    conn.query(q)
  File "/home/sale/projects/coursework/iep_project/store_management_system/development/user_management_system/authentication_service/venv/lib/python3.10/site-packages/pymysql/connections.py", line 558, in query
    self._affected_rows = self._read_query_result(unbuffered=unbuffered)
  File "/home/sale/projects/coursework/iep_project/store_management_system/development/user_management_system/authentication_service/venv/lib/python3.10/site-packages/pymysql/connections.py", line 822, in _read_query_result
    result.read()
  File "/home/sale/projects/coursework/iep_project/store_management_system/development/user_management_system/authentication_service/venv/lib/python3.10/site-packages/pymysql/connections.py", line 1200, in read
    first_packet = self.connection._read_packet()
  File "/home/sale/projects/coursework/iep_project/store_management_system/development/user_management_system/authentication_service/venv/lib/python3.10/site-packages/pymysql/connections.py", line 772, in _read_packet
    packet.raise_for_error()
  File "/home/sale/projects/coursework/iep_project/store_management_system/development/user_management_system/authentication_service/venv/lib/python3.10/site-packages/pymysql/protocol.py", line 221, in raise_for_error
    err.raise_mysql_exception(self._data)
  File "/home/sale/projects/coursework/iep_project/store_management_system/development/user_management_system/authentication_service/venv/lib/python3.10/site-packages/pymysql/err.py", line 143, in raise_mysql_exception
    raise errorclass(errno, errval)
sqlalchemy.exc.OperationalError: (pymysql.err.OperationalError) (1049, "Unknown database 'authentication'")
[SQL: INSERT INTO users (email, forename, surname, password) VALUES (%(email)s, %(forename)s, %(surname)s, %(password)s)]
[parameters: {'email': 'onlymoney@gmail.com', 'forename': 'John', 'surname': 'Doe', 'password': 'Aaaaaaaa1'}]
(Background on this error at: http://sqlalche.me/e/13/e3q8)
2023-08-29 14:13:00 [ERROR] Failed to register courier
Traceback (most recent call last):
  File "/home/sale/projects/coursework/iep_project/store_management_system/development/user_management_system/authentication_service/venv/lib/python3.10/site-packages/sqlalchemy/engine/base.py", line 1276, in _execute_context
    self.dialect.do_execute(
  File "/home/sale/projects/coursework/iep_project/store_management_system/development/user_management_system/authentication_service/venv/lib/python3.10/site-packages/sqlalchemy/engine/default.py", line 608, in do_execute
    cursor.execute(statement, parameters)
  File "/home/sale/projects/coursework/iep_project/store_management_system/development/user_management_system/authentication_service/venv/lib/python3.10/site-packages/pymysql/cursors.py", line 153, in execute
    result = self._query(query)
  File "/home/sale/projects/coursework/iep_project/store_management_system/development/user_management_system/authentication_service/venv/lib/python3.10/site-packages/pymysql/cursors.py", line 322, in _query
    conn.query(q)
  File "/home/sale/projects/coursework/iep_project/store_management_system/development/user_management_system/authentication_service/venv/lib/python3.10/site-packages/pymysql/connections.py", line 558, in query
    self._affected_rows = self._read_query_result(unbuffered=unbuffered)
  File "/home/sale/projects/coursework/iep_project/store_management_system/development/user_management_system/authentication_service/venv/lib/python3.10/site-packages/pymysql/connections.py", line 822, in _read_query_result
    result.read()
  File "/home/sale/projects/coursework/iep_project/store_management_system/development/user_management_system/authentication_service/venv/lib/python3.10/site-packages/pymysql/connections.py", line 1200, in read
    first_packet = self.connection._read_packet()
  File "/home/sale/projects/coursework/iep_project/store_management_system/development/user_management_system/authentication_service/venv/lib/python3.10/site-packages/pymysql/connections.py", line 772, in _read_packet
    packet.raise_for_error()
  File "/home/sale/projects/coursework/iep_project/store_management_system/development/user_management_system/authentication_service/venv/lib/python3.10/site-packages/pymysql/protocol.py", line 221, in raise_for_error
    err.raise_mysql_exception(self._data)
  File "/home/sale/projects/coursework/iep_project/store_management_system/development/user_management_system/authentication_service/venv/lib/python3.10/site-packages/pymysql/err.py", line 143, in raise_mysql_exception
    raise errorclass(errno, errval)
pymysql.err.OperationalError: (1049, "Unknown database 'authentication'")

The above exception was the direct cause of the following exception:

Traceback (most recent call last):
  File "/home/sale/projects/coursework/iep_project/store_management_system/development/user_management_system/authentication_service/app/blueprints/register.py", line 100, in register_user_view
    raise e
  File "/home/sale/projects/coursework/iep_project/store_management_system/development/user_management_system/authentication_service/app/blueprints/register.py", line 87, in register_user_view
    db.session.flush()
  File "/home/sale/projects/coursework/iep_project/store_management_system/development/user_management_system/authentication_service/venv/lib/python3.10/site-packages/sqlalchemy/orm/scoping.py", line 163, in do
    return getattr(self.registry(), name)(*args, **kwargs)
  File "/home/sale/projects/coursework/iep_project/store_management_system/development/user_management_system/authentication_service/venv/lib/python3.10/site-packages/sqlalchemy/orm/session.py", line 2540, in flush
    self._flush(objects)
  File "/home/sale/projects/coursework/iep_project/store_management_system/development/user_management_system/authentication_service/venv/lib/python3.10/site-packages/sqlalchemy/orm/session.py", line 2681, in _flush
    with util.safe_reraise():
  File "/home/sale/projects/coursework/iep_project/store_management_system/development/user_management_system/authentication_service/venv/lib/python3.10/site-packages/sqlalchemy/util/langhelpers.py", line 68, in __exit__
    compat.raise_(
  File "/home/sale/projects/coursework/iep_project/store_management_system/development/user_management_system/authentication_service/venv/lib/python3.10/site-packages/sqlalchemy/util/compat.py", line 182, in raise_
    raise exception
  File "/home/sale/projects/coursework/iep_project/store_management_system/development/user_management_system/authentication_service/venv/lib/python3.10/site-packages/sqlalchemy/orm/session.py", line 2642, in _flush
    flush_context.execute()
  File "/home/sale/projects/coursework/iep_project/store_management_system/development/user_management_system/authentication_service/venv/lib/python3.10/site-packages/sqlalchemy/orm/unitofwork.py", line 422, in execute
    rec.execute(self)
  File "/home/sale/projects/coursework/iep_project/store_management_system/development/user_management_system/authentication_service/venv/lib/python3.10/site-packages/sqlalchemy/orm/unitofwork.py", line 586, in execute
    persistence.save_obj(
  File "/home/sale/projects/coursework/iep_project/store_management_system/development/user_management_system/authentication_service/venv/lib/python3.10/site-packages/sqlalchemy/orm/persistence.py", line 239, in save_obj
    _emit_insert_statements(
  File "/home/sale/projects/coursework/iep_project/store_management_system/development/user_management_system/authentication_service/venv/lib/python3.10/site-packages/sqlalchemy/orm/persistence.py", line 1135, in _emit_insert_statements
    result = cached_connections[connection].execute(
  File "/home/sale/projects/coursework/iep_project/store_management_system/development/user_management_system/authentication_service/venv/lib/python3.10/site-packages/sqlalchemy/engine/base.py", line 1011, in execute
    return meth(self, multiparams, params)
  File "/home/sale/projects/coursework/iep_project/store_management_system/development/user_management_system/authentication_service/venv/lib/python3.10/site-packages/sqlalchemy/sql/elements.py", line 298, in _execute_on_connection
    return connection._execute_clauseelement(self, multiparams, params)
  File "/home/sale/projects/coursework/iep_project/store_management_system/development/user_management_system/authentication_service/venv/lib/python3.10/site-packages/sqlalchemy/engine/base.py", line 1124, in _execute_clauseelement
    ret = self._execute_context(
  File "/home/sale/projects/coursework/iep_project/store_management_system/development/user_management_system/authentication_service/venv/lib/python3.10/site-packages/sqlalchemy/engine/base.py", line 1316, in _execute_context
    self._handle_dbapi_exception(
  File "/home/sale/projects/coursework/iep_project/store_management_system/development/user_management_system/authentication_service/venv/lib/python3.10/site-packages/sqlalchemy/engine/base.py", line 1510, in _handle_dbapi_exception
    util.raise_(
  File "/home/sale/projects/coursework/iep_project/store_management_system/development/user_management_system/authentication_service/venv/lib/python3.10/site-packages/sqlalchemy/util/compat.py", line 182, in raise_
    raise exception
  File "/home/sale/projects/coursework/iep_project/store_management_system/development/user_management_system/authentication_service/venv/lib/python3.10/site-packages/sqlalchemy/engine/base.py", line 1276, in _execute_context
    self.dialect.do_execute(
  File "/home/sale/projects/coursework/iep_project/store_management_system/development/user_management_system/authentication_service/venv/lib/python3.10/site-packages/sqlalchemy/engine/default.py", line 608, in do_execute
    cursor.execute(statement, parameters)
  File "/home/sale/projects/coursework/iep_project/store_management_system/development/user_management_system/authentication_service/venv/lib/python3.10/site-packages/pymysql/cursors.py", line 153, in execute
    result = self._query(query)
  File "/home/sale/projects/coursework/iep_project/store_management_system/development/user_management_system/authentication_service/venv/lib/python3.10/site-packages/pymysql/cursors.py", line 322, in _query
    conn.query(q)
  File "/home/sale/projects/coursework/iep_project/store_management_system/development/user_management_system/authentication_service/venv/lib/python3.10/site-packages/pymysql/connections.py", line 558, in query
    self._affected_rows = self._read_query_result(unbuffered=unbuffered)
  File "/home/sale/projects/coursework/iep_project/store_management_system/development/user_management_system/authentication_service/venv/lib/python3.10/site-packages/pymysql/connections.py", line 822, in _read_query_result
    result.read()
  File "/home/sale/projects/coursework/iep_project/store_management_system/development/user_management_system/authentication_service/venv/lib/python3.10/site-packages/pymysql/connections.py", line 1200, in read
    first_packet = self.connection._read_packet()
  File "/home/sale/projects/coursework/iep_project/store_management_system/development/user_management_system/authentication_service/venv/lib/python3.10/site-packages/pymysql/connections.py", line 772, in _read_packet
    packet.raise_for_error()
  File "/home/sale/projects/coursework/iep_project/store_management_system/development/user_management_system/authentication_service/venv/lib/python3.10/site-packages/pymysql/protocol.py", line 221, in raise_for_error
    err.raise_mysql_exception(self._data)
  File "/home/sale/projects/coursework/iep_project/store_management_system/development/user_management_system/authentication_service/venv/lib/python3.10/site-packages/pymysql/err.py", line 143, in raise_mysql_exception
    raise errorclass(errno, errval)
sqlalchemy.exc.OperationalError: (pymysql.err.OperationalError) (1049, "Unknown database 'authentication'")
[SQL: INSERT INTO users (email, forename, surname, password) VALUES (%(email)s, %(forename)s, %(surname)s, %(password)s)]
[parameters: {'email': 'onlymoney@gmail.com', 'forename': 'John', 'surname': 'Doe', 'password': 'Aaaaaaaa1'}]
(Background on this error at: http://sqlalche.me/e/13/e3q8)
2023-08-29 14:13:00 [ERROR] Failed to login
Traceback (most recent call last):
  File "/home/sale/projects/coursework/iep_project/store_management_system/development/user_management_system/authentication_service/venv/lib/python3.10/site-packages/sqlalchemy/engine/base.py", line 1276, in _execute_context
    self.dialect.do_execute(
  File "/home/sale/projects/coursework/iep_project/store_management_system/development/user_management_system/authentication_service/venv/lib/python3.10/site-packages/sqlalchemy/engine/default.py", line 608, in do_execute
    cursor.execute(statement, parameters)
  File "/home/sale/projects/coursework/iep_project/store_management_system/development/user_management_system/authentication_service/venv/lib/python3.10/site-packages/pymysql/cursors.py", line 153, in execute
    result = self._query(query)
  File "/home/sale/projects/coursework/iep_project/store_management_system/development/user_management_system/authentication_service/venv/lib/python3.10/site-packages/pymysql/cursors.py", line 322, in _query
    conn.query(q)
  File "/home/sale/projects/coursework/iep_project/store_management_system/development/user_management_system/authentication_service/venv/lib/python3.10/site-packages/pymysql/connections.py", line 558, in query
    self._affected_rows = self._read_query_result(unbuffered=unbuffered)
  File "/home/sale/projects/coursework/iep_project/store_management_system/development/user_management_system/authentication_service/venv/lib/python3.10/site-packages/pymysql/connections.py", line 822, in _read_query_result
    result.read()
  File "/home/sale/projects/coursework/iep_project/store_management_system/development/user_management_system/authentication_service/venv/lib/python3.10/site-packages/pymysql/connections.py", line 1200, in read
    first_packet = self.connection._read_packet()
  File "/home/sale/projects/coursework/iep_project/store_management_system/development/user_management_system/authentication_service/venv/lib/python3.10/site-packages/pymysql/connections.py", line 772, in _read_packet
    packet.raise_for_error()
  File "/home/sale/projects/coursework/iep_project/store_management_system/development/user_management_system/authentication_service/venv/lib/python3.10/site-packages/pymysql/protocol.py", line 221, in raise_for_error
    err.raise_mysql_exception(self._data)
  File "/home/sale/projects/coursework/iep_project/store_management_system/development/user_management_system/authentication_service/venv/lib/python3.10/site-packages/pymysql/err.py", line 143, in raise_mysql_exception
    raise errorclass(errno, errval)
pymysql.err.OperationalError: (1049, "Unknown database 'authentication'")

The above exception was the direct cause of the following exception:

Traceback (most recent call last):
  File "/home/sale/projects/coursework/iep_project/store_management_system/development/user_management_system/authentication_service/app/blueprints/login.py", line 78, in login_user
    ).first()
  File "/home/sale/projects/coursework/iep_project/store_management_system/development/user_management_system/authentication_service/venv/lib/python3.10/site-packages/sqlalchemy/orm/query.py", line 3429, in first
    ret = list(self[0:1])
  File "/home/sale/projects/coursework/iep_project/store_management_system/development/user_management_system/authentication_service/venv/lib/python3.10/site-packages/sqlalchemy/orm/query.py", line 3203, in __getitem__
    return list(res)
  File "/home/sale/projects/coursework/iep_project/store_management_system/development/user_management_system/authentication_service/venv/lib/python3.10/site-packages/sqlalchemy/orm/query.py", line 3535, in __iter__
    return self._execute_and_instances(context)
  File "/home/sale/projects/coursework/iep_project/store_management_system/development/user_management_system/authentication_service/venv/lib/python3.10/site-packages/sqlalchemy/orm/query.py", line 3560, in _execute_and_instances
    result = conn.execute(querycontext.statement, self._params)
  File "/home/sale/projects/coursework/iep_project/store_management_system/development/user_management_system/authentication_service/venv/lib/python3.10/site-packages/sqlalchemy/engine/base.py", line 1011, in execute
    return meth(self, multiparams, params)
  File "/home/sale/projects/coursework/iep_project/store_management_system/development/user_management_system/authentication_service/venv/lib/python3.10/site-packages/sqlalchemy/sql/elements.py", line 298, in _execute_on_connection
    return connection._execute_clauseelement(self, multiparams, params)
  File "/home/sale/projects/coursework/iep_project/store_management_system/development/user_management_system/authentication_service/venv/lib/python3.10/site-packages/sqlalchemy/engine/base.py", line 1124, in _execute_clauseelement
    ret = self._execute_context(
  File "/home/sale/projects/coursework/iep_project/store_management_system/development/user_management_system/authentication_service/venv/lib/python3.10/site-packages/sqlalchemy/engine/base.py", line 1316, in _execute_context
    self._handle_dbapi_exception(
  File "/home/sale/projects/coursework/iep_project/store_management_system/development/user_management_system/authentication_service/venv/lib/python3.10/site-packages/sqlalchemy/engine/base.py", line 1510, in _handle_dbapi_exception
    util.raise_(
  File "/home/sale/projects/coursework/iep_project/store_management_system/development/user_management_system/authentication_service/venv/lib/python3.10/site-packages/sqlalchemy/util/compat.py", line 182, in raise_
    raise exception
  File "/home/sale/projects/coursework/iep_project/store_management_system/development/user_management_system/authentication_service/venv/lib/python3.10/site-packages/sqlalchemy/engine/base.py", line 1276, in _execute_context
    self.dialect.do_execute(
  File "/home/sale/projects/coursework/iep_project/store_management_system/development/user_management_system/authentication_service/venv/lib/python3.10/site-packages/sqlalchemy/engine/default.py", line 608, in do_execute
    cursor.execute(statement, parameters)
  File "/home/sale/projects/coursework/iep_project/store_management_system/development/user_management_system/authentication_service/venv/lib/python3.10/site-packages/pymysql/cursors.py", line 153, in execute
    result = self._query(query)
  File "/home/sale/projects/coursework/iep_project/store_management_system/development/user_management_system/authentication_service/venv/lib/python3.10/site-packages/pymysql/cursors.py", line 322, in _query
    conn.query(q)
  File "/home/sale/projects/coursework/iep_project/store_management_system/development/user_management_system/authentication_service/venv/lib/python3.10/site-packages/pymysql/connections.py", line 558, in query
    self._affected_rows = self._read_query_result(unbuffered=unbuffered)
  File "/home/sale/projects/coursework/iep_project/store_management_system/development/user_management_system/authentication_service/venv/lib/python3.10/site-packages/pymysql/connections.py", line 822, in _read_query_result
    result.read()
  File "/home/sale/projects/coursework/iep_project/store_management_system/development/user_management_system/authentication_service/venv/lib/python3.10/site-packages/pymysql/connections.py", line 1200, in read
    first_packet = self.connection._read_packet()
  File "/home/sale/projects/coursework/iep_project/store_management_system/development/user_management_system/authentication_service/venv/lib/python3.10/site-packages/pymysql/connections.py", line 772, in _read_packet
    packet.raise_for_error()
  File "/home/sale/projects/coursework/iep_project/store_management_system/development/user_management_system/authentication_service/venv/lib/python3.10/site-packages/pymysql/protocol.py", line 221, in raise_for_error
    err.raise_mysql_exception(self._data)
  File "/home/sale/projects/coursework/iep_project/store_management_system/development/user_management_system/authentication_service/venv/lib/python3.10/site-packages/pymysql/err.py", line 143, in raise_mysql_exception
    raise errorclass(errno, errval)
sqlalchemy.exc.OperationalError: (pymysql.err.OperationalError) (1049, "Unknown database 'authentication'")
[SQL: SELECT users.id AS users_id, users.email AS users_email, users.forename AS users_forename, users.surname AS users_surname, users.password AS users_password 
FROM users 
WHERE users.email = %(email_1)s AND users.password = %(password_1)s 
 LIMIT %(param_1)s]
[parameters: {'email_1': 'john@gmail.com', 'password_1': '123', 'param_1': 1}]
(Background on this error at: http://sqlalche.me/e/13/e3q8)
2023-08-29 14:13:00 [ERROR] Failed to login
Traceback (most recent call last):
  File "/home/sale/projects/coursework/iep_project/store_management_system/development/user_management_system/authentication_service/venv/lib/python3.10/site-packages/sqlalchemy/engine/base.py", line 1276, in _execute_context
    self.dialect.do_execute(
  File "/home/sale/projects/coursework/iep_project/store_management_system/development/user_management_system/authentication_service/venv/lib/python3.10/site-packages/sqlalchemy/engine/default.py", line 608, in do_execute
    cursor.execute(statement, parameters)
  File "/home/sale/projects/coursework/iep_project/store_management_system/development/user_management_system/authentication_service/venv/lib/python3.10/site-packages/pymysql/cursors.py", line 153, in execute
    result = self._query(query)
  File "/home/sale/projects/coursework/iep_project/store_management_system/development/user_management_system/authentication_service/venv/lib/python3.10/site-packages/pymysql/cursors.py", line 322, in _query
    conn.query(q)
  File "/home/sale/projects/coursework/iep_project/store_management_system/development/user_management_system/authentication_service/venv/lib/python3.10/site-packages/pymysql/connections.py", line 558, in query
    self._affected_rows = self._read_query_result(unbuffered=unbuffered)
  File "/home/sale/projects/coursework/iep_project/store_management_system/development/user_management_system/authentication_service/venv/lib/python3.10/site-packages/pymysql/connections.py", line 822, in _read_query_result
    result.read()
  File "/home/sale/projects/coursework/iep_project/store_management_system/development/user_management_system/authentication_service/venv/lib/python3.10/site-packages/pymysql/connections.py", line 1200, in read
    first_packet = self.connection._read_packet()
  File "/home/sale/projects/coursework/iep_project/store_management_system/development/user_management_system/authentication_service/venv/lib/python3.10/site-packages/pymysql/connections.py", line 772, in _read_packet
    packet.raise_for_error()
  File "/home/sale/projects/coursework/iep_project/store_management_system/development/user_management_system/authentication_service/venv/lib/python3.10/site-packages/pymysql/protocol.py", line 221, in raise_for_error
    err.raise_mysql_exception(self._data)
  File "/home/sale/projects/coursework/iep_project/store_management_system/development/user_management_system/authentication_service/venv/lib/python3.10/site-packages/pymysql/err.py", line 143, in raise_mysql_exception
    raise errorclass(errno, errval)
pymysql.err.OperationalError: (1049, "Unknown database 'authentication'")

The above exception was the direct cause of the following exception:

Traceback (most recent call last):
  File "/home/sale/projects/coursework/iep_project/store_management_system/development/user_management_system/authentication_service/app/blueprints/login.py", line 78, in login_user
    ).first()
  File "/home/sale/projects/coursework/iep_project/store_management_system/development/user_management_system/authentication_service/venv/lib/python3.10/site-packages/sqlalchemy/orm/query.py", line 3429, in first
    ret = list(self[0:1])
  File "/home/sale/projects/coursework/iep_project/store_management_system/development/user_management_system/authentication_service/venv/lib/python3.10/site-packages/sqlalchemy/orm/query.py", line 3203, in __getitem__
    return list(res)
  File "/home/sale/projects/coursework/iep_project/store_management_system/development/user_management_system/authentication_service/venv/lib/python3.10/site-packages/sqlalchemy/orm/query.py", line 3535, in __iter__
    return self._execute_and_instances(context)
  File "/home/sale/projects/coursework/iep_project/store_management_system/development/user_management_system/authentication_service/venv/lib/python3.10/site-packages/sqlalchemy/orm/query.py", line 3560, in _execute_and_instances
    result = conn.execute(querycontext.statement, self._params)
  File "/home/sale/projects/coursework/iep_project/store_management_system/development/user_management_system/authentication_service/venv/lib/python3.10/site-packages/sqlalchemy/engine/base.py", line 1011, in execute
    return meth(self, multiparams, params)
  File "/home/sale/projects/coursework/iep_project/store_management_system/development/user_management_system/authentication_service/venv/lib/python3.10/site-packages/sqlalchemy/sql/elements.py", line 298, in _execute_on_connection
    return connection._execute_clauseelement(self, multiparams, params)
  File "/home/sale/projects/coursework/iep_project/store_management_system/development/user_management_system/authentication_service/venv/lib/python3.10/site-packages/sqlalchemy/engine/base.py", line 1124, in _execute_clauseelement
    ret = self._execute_context(
  File "/home/sale/projects/coursework/iep_project/store_management_system/development/user_management_system/authentication_service/venv/lib/python3.10/site-packages/sqlalchemy/engine/base.py", line 1316, in _execute_context
    self._handle_dbapi_exception(
  File "/home/sale/projects/coursework/iep_project/store_management_system/development/user_management_system/authentication_service/venv/lib/python3.10/site-packages/sqlalchemy/engine/base.py", line 1510, in _handle_dbapi_exception
    util.raise_(
  File "/home/sale/projects/coursework/iep_project/store_management_system/development/user_management_system/authentication_service/venv/lib/python3.10/site-packages/sqlalchemy/util/compat.py", line 182, in raise_
    raise exception
  File "/home/sale/projects/coursework/iep_project/store_management_system/development/user_management_system/authentication_service/venv/lib/python3.10/site-packages/sqlalchemy/engine/base.py", line 1276, in _execute_context
    self.dialect.do_execute(
  File "/home/sale/projects/coursework/iep_project/store_management_system/development/user_management_system/authentication_service/venv/lib/python3.10/site-packages/sqlalchemy/engine/default.py", line 608, in do_execute
    cursor.execute(statement, parameters)
  File "/home/sale/projects/coursework/iep_project/store_management_system/development/user_management_system/authentication_service/venv/lib/python3.10/site-packages/pymysql/cursors.py", line 153, in execute
    result = self._query(query)
  File "/home/sale/projects/coursework/iep_project/store_management_system/development/user_management_system/authentication_service/venv/lib/python3.10/site-packages/pymysql/cursors.py", line 322, in _query
    conn.query(q)
  File "/home/sale/projects/coursework/iep_project/store_management_system/development/user_management_system/authentication_service/venv/lib/python3.10/site-packages/pymysql/connections.py", line 558, in query
    self._affected_rows = self._read_query_result(unbuffered=unbuffered)
  File "/home/sale/projects/coursework/iep_project/store_management_system/development/user_management_system/authentication_service/venv/lib/python3.10/site-packages/pymysql/connections.py", line 822, in _read_query_result
    result.read()
  File "/home/sale/projects/coursework/iep_project/store_management_system/development/user_management_system/authentication_service/venv/lib/python3.10/site-packages/pymysql/connections.py", line 1200, in read
    first_packet = self.connection._read_packet()
  File "/home/sale/projects/coursework/iep_project/store_management_system/development/user_management_system/authentication_service/venv/lib/python3.10/site-packages/pymysql/connections.py", line 772, in _read_packet
    packet.raise_for_error()
  File "/home/sale/projects/coursework/iep_project/store_management_system/development/user_management_system/authentication_service/venv/lib/python3.10/site-packages/pymysql/protocol.py", line 221, in raise_for_error
    err.raise_mysql_exception(self._data)
  File "/home/sale/projects/coursework/iep_project/store_management_system/development/user_management_system/authentication_service/venv/lib/python3.10/site-packages/pymysql/err.py", line 143, in raise_mysql_exception
    raise errorclass(errno, errval)
sqlalchemy.exc.OperationalError: (pymysql.err.OperationalError) (1049, "Unknown database 'authentication'")
[SQL: SELECT users.id AS users_id, users.email AS users_email, users.forename AS users_forename, users.surname AS users_surname, users.password AS users_password 
FROM users 
WHERE users.email = %(email_1)s AND users.password = %(password_1)s 
 LIMIT %(param_1)s]
[parameters: {'email_1': 'jane@gmail.com', 'password_1': 'aA123456', 'param_1': 1}]
(Background on this error at: http://sqlalche.me/e/13/e3q8)
2023-08-29 14:13:00 [ERROR] Failed to login
Traceback (most recent call last):
  File "/home/sale/projects/coursework/iep_project/store_management_system/development/user_management_system/authentication_service/venv/lib/python3.10/site-packages/sqlalchemy/engine/base.py", line 1276, in _execute_context
    self.dialect.do_execute(
  File "/home/sale/projects/coursework/iep_project/store_management_system/development/user_management_system/authentication_service/venv/lib/python3.10/site-packages/sqlalchemy/engine/default.py", line 608, in do_execute
    cursor.execute(statement, parameters)
  File "/home/sale/projects/coursework/iep_project/store_management_system/development/user_management_system/authentication_service/venv/lib/python3.10/site-packages/pymysql/cursors.py", line 153, in execute
    result = self._query(query)
  File "/home/sale/projects/coursework/iep_project/store_management_system/development/user_management_system/authentication_service/venv/lib/python3.10/site-packages/pymysql/cursors.py", line 322, in _query
    conn.query(q)
  File "/home/sale/projects/coursework/iep_project/store_management_system/development/user_management_system/authentication_service/venv/lib/python3.10/site-packages/pymysql/connections.py", line 558, in query
    self._affected_rows = self._read_query_result(unbuffered=unbuffered)
  File "/home/sale/projects/coursework/iep_project/store_management_system/development/user_management_system/authentication_service/venv/lib/python3.10/site-packages/pymysql/connections.py", line 822, in _read_query_result
    result.read()
  File "/home/sale/projects/coursework/iep_project/store_management_system/development/user_management_system/authentication_service/venv/lib/python3.10/site-packages/pymysql/connections.py", line 1200, in read
    first_packet = self.connection._read_packet()
  File "/home/sale/projects/coursework/iep_project/store_management_system/development/user_management_system/authentication_service/venv/lib/python3.10/site-packages/pymysql/connections.py", line 772, in _read_packet
    packet.raise_for_error()
  File "/home/sale/projects/coursework/iep_project/store_management_system/development/user_management_system/authentication_service/venv/lib/python3.10/site-packages/pymysql/protocol.py", line 221, in raise_for_error
    err.raise_mysql_exception(self._data)
  File "/home/sale/projects/coursework/iep_project/store_management_system/development/user_management_system/authentication_service/venv/lib/python3.10/site-packages/pymysql/err.py", line 143, in raise_mysql_exception
    raise errorclass(errno, errval)
pymysql.err.OperationalError: (1049, "Unknown database 'authentication'")

The above exception was the direct cause of the following exception:

Traceback (most recent call last):
  File "/home/sale/projects/coursework/iep_project/store_management_system/development/user_management_system/authentication_service/app/blueprints/login.py", line 78, in login_user
    ).first()
  File "/home/sale/projects/coursework/iep_project/store_management_system/development/user_management_system/authentication_service/venv/lib/python3.10/site-packages/sqlalchemy/orm/query.py", line 3429, in first
    ret = list(self[0:1])
  File "/home/sale/projects/coursework/iep_project/store_management_system/development/user_management_system/authentication_service/venv/lib/python3.10/site-packages/sqlalchemy/orm/query.py", line 3203, in __getitem__
    return list(res)
  File "/home/sale/projects/coursework/iep_project/store_management_system/development/user_management_system/authentication_service/venv/lib/python3.10/site-packages/sqlalchemy/orm/query.py", line 3535, in __iter__
    return self._execute_and_instances(context)
  File "/home/sale/projects/coursework/iep_project/store_management_system/development/user_management_system/authentication_service/venv/lib/python3.10/site-packages/sqlalchemy/orm/query.py", line 3560, in _execute_and_instances
    result = conn.execute(querycontext.statement, self._params)
  File "/home/sale/projects/coursework/iep_project/store_management_system/development/user_management_system/authentication_service/venv/lib/python3.10/site-packages/sqlalchemy/engine/base.py", line 1011, in execute
    return meth(self, multiparams, params)
  File "/home/sale/projects/coursework/iep_project/store_management_system/development/user_management_system/authentication_service/venv/lib/python3.10/site-packages/sqlalchemy/sql/elements.py", line 298, in _execute_on_connection
    return connection._execute_clauseelement(self, multiparams, params)
  File "/home/sale/projects/coursework/iep_project/store_management_system/development/user_management_system/authentication_service/venv/lib/python3.10/site-packages/sqlalchemy/engine/base.py", line 1124, in _execute_clauseelement
    ret = self._execute_context(
  File "/home/sale/projects/coursework/iep_project/store_management_system/development/user_management_system/authentication_service/venv/lib/python3.10/site-packages/sqlalchemy/engine/base.py", line 1316, in _execute_context
    self._handle_dbapi_exception(
  File "/home/sale/projects/coursework/iep_project/store_management_system/development/user_management_system/authentication_service/venv/lib/python3.10/site-packages/sqlalchemy/engine/base.py", line 1510, in _handle_dbapi_exception
    util.raise_(
  File "/home/sale/projects/coursework/iep_project/store_management_system/development/user_management_system/authentication_service/venv/lib/python3.10/site-packages/sqlalchemy/util/compat.py", line 182, in raise_
    raise exception
  File "/home/sale/projects/coursework/iep_project/store_management_system/development/user_management_system/authentication_service/venv/lib/python3.10/site-packages/sqlalchemy/engine/base.py", line 1276, in _execute_context
    self.dialect.do_execute(
  File "/home/sale/projects/coursework/iep_project/store_management_system/development/user_management_system/authentication_service/venv/lib/python3.10/site-packages/sqlalchemy/engine/default.py", line 608, in do_execute
    cursor.execute(statement, parameters)
  File "/home/sale/projects/coursework/iep_project/store_management_system/development/user_management_system/authentication_service/venv/lib/python3.10/site-packages/pymysql/cursors.py", line 153, in execute
    result = self._query(query)
  File "/home/sale/projects/coursework/iep_project/store_management_system/development/user_management_system/authentication_service/venv/lib/python3.10/site-packages/pymysql/cursors.py", line 322, in _query
    conn.query(q)
  File "/home/sale/projects/coursework/iep_project/store_management_system/development/user_management_system/authentication_service/venv/lib/python3.10/site-packages/pymysql/connections.py", line 558, in query
    self._affected_rows = self._read_query_result(unbuffered=unbuffered)
  File "/home/sale/projects/coursework/iep_project/store_management_system/development/user_management_system/authentication_service/venv/lib/python3.10/site-packages/pymysql/connections.py", line 822, in _read_query_result
    result.read()
  File "/home/sale/projects/coursework/iep_project/store_management_system/development/user_management_system/authentication_service/venv/lib/python3.10/site-packages/pymysql/connections.py", line 1200, in read
    first_packet = self.connection._read_packet()
  File "/home/sale/projects/coursework/iep_project/store_management_system/development/user_management_system/authentication_service/venv/lib/python3.10/site-packages/pymysql/connections.py", line 772, in _read_packet
    packet.raise_for_error()
  File "/home/sale/projects/coursework/iep_project/store_management_system/development/user_management_system/authentication_service/venv/lib/python3.10/site-packages/pymysql/protocol.py", line 221, in raise_for_error
    err.raise_mysql_exception(self._data)
  File "/home/sale/projects/coursework/iep_project/store_management_system/development/user_management_system/authentication_service/venv/lib/python3.10/site-packages/pymysql/err.py", line 143, in raise_mysql_exception
    raise errorclass(errno, errval)
sqlalchemy.exc.OperationalError: (pymysql.err.OperationalError) (1049, "Unknown database 'authentication'")
[SQL: SELECT users.id AS users_id, users.email AS users_email, users.forename AS users_forename, users.surname AS users_surname, users.password AS users_password 
FROM users 
WHERE users.email = %(email_1)s AND users.password = %(password_1)s 
 LIMIT %(param_1)s]
[parameters: {'email_1': 'john@gmail.com', 'password_1': 'aA123456', 'param_1': 1}]
(Background on this error at: http://sqlalche.me/e/13/e3q8)
2023-08-29 14:13:00 [ERROR] Failed to register courier
Traceback (most recent call last):
  File "/home/sale/projects/coursework/iep_project/store_management_system/development/user_management_system/authentication_service/venv/lib/python3.10/site-packages/sqlalchemy/engine/base.py", line 1276, in _execute_context
    self.dialect.do_execute(
  File "/home/sale/projects/coursework/iep_project/store_management_system/development/user_management_system/authentication_service/venv/lib/python3.10/site-packages/sqlalchemy/engine/default.py", line 608, in do_execute
    cursor.execute(statement, parameters)
  File "/home/sale/projects/coursework/iep_project/store_management_system/development/user_management_system/authentication_service/venv/lib/python3.10/site-packages/pymysql/cursors.py", line 153, in execute
    result = self._query(query)
  File "/home/sale/projects/coursework/iep_project/store_management_system/development/user_management_system/authentication_service/venv/lib/python3.10/site-packages/pymysql/cursors.py", line 322, in _query
    conn.query(q)
  File "/home/sale/projects/coursework/iep_project/store_management_system/development/user_management_system/authentication_service/venv/lib/python3.10/site-packages/pymysql/connections.py", line 558, in query
    self._affected_rows = self._read_query_result(unbuffered=unbuffered)
  File "/home/sale/projects/coursework/iep_project/store_management_system/development/user_management_system/authentication_service/venv/lib/python3.10/site-packages/pymysql/connections.py", line 822, in _read_query_result
    result.read()
  File "/home/sale/projects/coursework/iep_project/store_management_system/development/user_management_system/authentication_service/venv/lib/python3.10/site-packages/pymysql/connections.py", line 1200, in read
    first_packet = self.connection._read_packet()
  File "/home/sale/projects/coursework/iep_project/store_management_system/development/user_management_system/authentication_service/venv/lib/python3.10/site-packages/pymysql/connections.py", line 772, in _read_packet
    packet.raise_for_error()
  File "/home/sale/projects/coursework/iep_project/store_management_system/development/user_management_system/authentication_service/venv/lib/python3.10/site-packages/pymysql/protocol.py", line 221, in raise_for_error
    err.raise_mysql_exception(self._data)
  File "/home/sale/projects/coursework/iep_project/store_management_system/development/user_management_system/authentication_service/venv/lib/python3.10/site-packages/pymysql/err.py", line 143, in raise_mysql_exception
    raise errorclass(errno, errval)
pymysql.err.OperationalError: (1049, "Unknown database 'authentication'")

The above exception was the direct cause of the following exception:

Traceback (most recent call last):
  File "/home/sale/projects/coursework/iep_project/store_management_system/development/user_management_system/authentication_service/app/blueprints/register.py", line 100, in register_user_view
    raise e
  File "/home/sale/projects/coursework/iep_project/store_management_system/development/user_management_system/authentication_service/app/blueprints/register.py", line 87, in register_user_view
    db.session.flush()
  File "/home/sale/projects/coursework/iep_project/store_management_system/development/user_management_system/authentication_service/venv/lib/python3.10/site-packages/sqlalchemy/orm/scoping.py", line 163, in do
    return getattr(self.registry(), name)(*args, **kwargs)
  File "/home/sale/projects/coursework/iep_project/store_management_system/development/user_management_system/authentication_service/venv/lib/python3.10/site-packages/sqlalchemy/orm/session.py", line 2540, in flush
    self._flush(objects)
  File "/home/sale/projects/coursework/iep_project/store_management_system/development/user_management_system/authentication_service/venv/lib/python3.10/site-packages/sqlalchemy/orm/session.py", line 2681, in _flush
    with util.safe_reraise():
  File "/home/sale/projects/coursework/iep_project/store_management_system/development/user_management_system/authentication_service/venv/lib/python3.10/site-packages/sqlalchemy/util/langhelpers.py", line 68, in __exit__
    compat.raise_(
  File "/home/sale/projects/coursework/iep_project/store_management_system/development/user_management_system/authentication_service/venv/lib/python3.10/site-packages/sqlalchemy/util/compat.py", line 182, in raise_
    raise exception
  File "/home/sale/projects/coursework/iep_project/store_management_system/development/user_management_system/authentication_service/venv/lib/python3.10/site-packages/sqlalchemy/orm/session.py", line 2642, in _flush
    flush_context.execute()
  File "/home/sale/projects/coursework/iep_project/store_management_system/development/user_management_system/authentication_service/venv/lib/python3.10/site-packages/sqlalchemy/orm/unitofwork.py", line 422, in execute
    rec.execute(self)
  File "/home/sale/projects/coursework/iep_project/store_management_system/development/user_management_system/authentication_service/venv/lib/python3.10/site-packages/sqlalchemy/orm/unitofwork.py", line 586, in execute
    persistence.save_obj(
  File "/home/sale/projects/coursework/iep_project/store_management_system/development/user_management_system/authentication_service/venv/lib/python3.10/site-packages/sqlalchemy/orm/persistence.py", line 239, in save_obj
    _emit_insert_statements(
  File "/home/sale/projects/coursework/iep_project/store_management_system/development/user_management_system/authentication_service/venv/lib/python3.10/site-packages/sqlalchemy/orm/persistence.py", line 1135, in _emit_insert_statements
    result = cached_connections[connection].execute(
  File "/home/sale/projects/coursework/iep_project/store_management_system/development/user_management_system/authentication_service/venv/lib/python3.10/site-packages/sqlalchemy/engine/base.py", line 1011, in execute
    return meth(self, multiparams, params)
  File "/home/sale/projects/coursework/iep_project/store_management_system/development/user_management_system/authentication_service/venv/lib/python3.10/site-packages/sqlalchemy/sql/elements.py", line 298, in _execute_on_connection
    return connection._execute_clauseelement(self, multiparams, params)
  File "/home/sale/projects/coursework/iep_project/store_management_system/development/user_management_system/authentication_service/venv/lib/python3.10/site-packages/sqlalchemy/engine/base.py", line 1124, in _execute_clauseelement
    ret = self._execute_context(
  File "/home/sale/projects/coursework/iep_project/store_management_system/development/user_management_system/authentication_service/venv/lib/python3.10/site-packages/sqlalchemy/engine/base.py", line 1316, in _execute_context
    self._handle_dbapi_exception(
  File "/home/sale/projects/coursework/iep_project/store_management_system/development/user_management_system/authentication_service/venv/lib/python3.10/site-packages/sqlalchemy/engine/base.py", line 1510, in _handle_dbapi_exception
    util.raise_(
  File "/home/sale/projects/coursework/iep_project/store_management_system/development/user_management_system/authentication_service/venv/lib/python3.10/site-packages/sqlalchemy/util/compat.py", line 182, in raise_
    raise exception
  File "/home/sale/projects/coursework/iep_project/store_management_system/development/user_management_system/authentication_service/venv/lib/python3.10/site-packages/sqlalchemy/engine/base.py", line 1276, in _execute_context
    self.dialect.do_execute(
  File "/home/sale/projects/coursework/iep_project/store_management_system/development/user_management_system/authentication_service/venv/lib/python3.10/site-packages/sqlalchemy/engine/default.py", line 608, in do_execute
    cursor.execute(statement, parameters)
  File "/home/sale/projects/coursework/iep_project/store_management_system/development/user_management_system/authentication_service/venv/lib/python3.10/site-packages/pymysql/cursors.py", line 153, in execute
    result = self._query(query)
  File "/home/sale/projects/coursework/iep_project/store_management_system/development/user_management_system/authentication_service/venv/lib/python3.10/site-packages/pymysql/cursors.py", line 322, in _query
    conn.query(q)
  File "/home/sale/projects/coursework/iep_project/store_management_system/development/user_management_system/authentication_service/venv/lib/python3.10/site-packages/pymysql/connections.py", line 558, in query
    self._affected_rows = self._read_query_result(unbuffered=unbuffered)
  File "/home/sale/projects/coursework/iep_project/store_management_system/development/user_management_system/authentication_service/venv/lib/python3.10/site-packages/pymysql/connections.py", line 822, in _read_query_result
    result.read()
  File "/home/sale/projects/coursework/iep_project/store_management_system/development/user_management_system/authentication_service/venv/lib/python3.10/site-packages/pymysql/connections.py", line 1200, in read
    first_packet = self.connection._read_packet()
  File "/home/sale/projects/coursework/iep_project/store_management_system/development/user_management_system/authentication_service/venv/lib/python3.10/site-packages/pymysql/connections.py", line 772, in _read_packet
    packet.raise_for_error()
  File "/home/sale/projects/coursework/iep_project/store_management_system/development/user_management_system/authentication_service/venv/lib/python3.10/site-packages/pymysql/protocol.py", line 221, in raise_for_error
    err.raise_mysql_exception(self._data)
  File "/home/sale/projects/coursework/iep_project/store_management_system/development/user_management_system/authentication_service/venv/lib/python3.10/site-packages/pymysql/err.py", line 143, in raise_mysql_exception
    raise errorclass(errno, errval)
sqlalchemy.exc.OperationalError: (pymysql.err.OperationalError) (1049, "Unknown database 'authentication'")
[SQL: INSERT INTO users (email, forename, surname, password) VALUES (%(email)s, %(forename)s, %(surname)s, %(password)s)]
[parameters: {'email': 'john@gmail.com', 'forename': 'John', 'surname': 'Doe', 'password': 'aA123456'}]
(Background on this error at: http://sqlalche.me/e/13/e3q8)
2023-08-29 14:13:00 [ERROR] Failed to register customer
Traceback (most recent call last):
  File "/home/sale/projects/coursework/iep_project/store_management_system/development/user_management_system/authentication_service/venv/lib/python3.10/site-packages/sqlalchemy/engine/base.py", line 1276, in _execute_context
    self.dialect.do_execute(
  File "/home/sale/projects/coursework/iep_project/store_management_system/development/user_management_system/authentication_service/venv/lib/python3.10/site-packages/sqlalchemy/engine/default.py", line 608, in do_execute
    cursor.execute(statement, parameters)
  File "/home/sale/projects/coursework/iep_project/store_management_system/development/user_management_system/authentication_service/venv/lib/python3.10/site-packages/pymysql/cursors.py", line 153, in execute
    result = self._query(query)
  File "/home/sale/projects/coursework/iep_project/store_management_system/development/user_management_system/authentication_service/venv/lib/python3.10/site-packages/pymysql/cursors.py", line 322, in _query
    conn.query(q)
  File "/home/sale/projects/coursework/iep_project/store_management_system/development/user_management_system/authentication_service/venv/lib/python3.10/site-packages/pymysql/connections.py", line 558, in query
    self._affected_rows = self._read_query_result(unbuffered=unbuffered)
  File "/home/sale/projects/coursework/iep_project/store_management_system/development/user_management_system/authentication_service/venv/lib/python3.10/site-packages/pymysql/connections.py", line 822, in _read_query_result
    result.read()
  File "/home/sale/projects/coursework/iep_project/store_management_system/development/user_management_system/authentication_service/venv/lib/python3.10/site-packages/pymysql/connections.py", line 1200, in read
    first_packet = self.connection._read_packet()
  File "/home/sale/projects/coursework/iep_project/store_management_system/development/user_management_system/authentication_service/venv/lib/python3.10/site-packages/pymysql/connections.py", line 772, in _read_packet
    packet.raise_for_error()
  File "/home/sale/projects/coursework/iep_project/store_management_system/development/user_management_system/authentication_service/venv/lib/python3.10/site-packages/pymysql/protocol.py", line 221, in raise_for_error
    err.raise_mysql_exception(self._data)
  File "/home/sale/projects/coursework/iep_project/store_management_system/development/user_management_system/authentication_service/venv/lib/python3.10/site-packages/pymysql/err.py", line 143, in raise_mysql_exception
    raise errorclass(errno, errval)
pymysql.err.OperationalError: (1049, "Unknown database 'authentication'")

The above exception was the direct cause of the following exception:

Traceback (most recent call last):
  File "/home/sale/projects/coursework/iep_project/store_management_system/development/user_management_system/authentication_service/app/blueprints/register.py", line 100, in register_user_view
    raise e
  File "/home/sale/projects/coursework/iep_project/store_management_system/development/user_management_system/authentication_service/app/blueprints/register.py", line 87, in register_user_view
    db.session.flush()
  File "/home/sale/projects/coursework/iep_project/store_management_system/development/user_management_system/authentication_service/venv/lib/python3.10/site-packages/sqlalchemy/orm/scoping.py", line 163, in do
    return getattr(self.registry(), name)(*args, **kwargs)
  File "/home/sale/projects/coursework/iep_project/store_management_system/development/user_management_system/authentication_service/venv/lib/python3.10/site-packages/sqlalchemy/orm/session.py", line 2540, in flush
    self._flush(objects)
  File "/home/sale/projects/coursework/iep_project/store_management_system/development/user_management_system/authentication_service/venv/lib/python3.10/site-packages/sqlalchemy/orm/session.py", line 2681, in _flush
    with util.safe_reraise():
  File "/home/sale/projects/coursework/iep_project/store_management_system/development/user_management_system/authentication_service/venv/lib/python3.10/site-packages/sqlalchemy/util/langhelpers.py", line 68, in __exit__
    compat.raise_(
  File "/home/sale/projects/coursework/iep_project/store_management_system/development/user_management_system/authentication_service/venv/lib/python3.10/site-packages/sqlalchemy/util/compat.py", line 182, in raise_
    raise exception
  File "/home/sale/projects/coursework/iep_project/store_management_system/development/user_management_system/authentication_service/venv/lib/python3.10/site-packages/sqlalchemy/orm/session.py", line 2642, in _flush
    flush_context.execute()
  File "/home/sale/projects/coursework/iep_project/store_management_system/development/user_management_system/authentication_service/venv/lib/python3.10/site-packages/sqlalchemy/orm/unitofwork.py", line 422, in execute
    rec.execute(self)
  File "/home/sale/projects/coursework/iep_project/store_management_system/development/user_management_system/authentication_service/venv/lib/python3.10/site-packages/sqlalchemy/orm/unitofwork.py", line 586, in execute
    persistence.save_obj(
  File "/home/sale/projects/coursework/iep_project/store_management_system/development/user_management_system/authentication_service/venv/lib/python3.10/site-packages/sqlalchemy/orm/persistence.py", line 239, in save_obj
    _emit_insert_statements(
  File "/home/sale/projects/coursework/iep_project/store_management_system/development/user_management_system/authentication_service/venv/lib/python3.10/site-packages/sqlalchemy/orm/persistence.py", line 1135, in _emit_insert_statements
    result = cached_connections[connection].execute(
  File "/home/sale/projects/coursework/iep_project/store_management_system/development/user_management_system/authentication_service/venv/lib/python3.10/site-packages/sqlalchemy/engine/base.py", line 1011, in execute
    return meth(self, multiparams, params)
  File "/home/sale/projects/coursework/iep_project/store_management_system/development/user_management_system/authentication_service/venv/lib/python3.10/site-packages/sqlalchemy/sql/elements.py", line 298, in _execute_on_connection
    return connection._execute_clauseelement(self, multiparams, params)
  File "/home/sale/projects/coursework/iep_project/store_management_system/development/user_management_system/authentication_service/venv/lib/python3.10/site-packages/sqlalchemy/engine/base.py", line 1124, in _execute_clauseelement
    ret = self._execute_context(
  File "/home/sale/projects/coursework/iep_project/store_management_system/development/user_management_system/authentication_service/venv/lib/python3.10/site-packages/sqlalchemy/engine/base.py", line 1316, in _execute_context
    self._handle_dbapi_exception(
  File "/home/sale/projects/coursework/iep_project/store_management_system/development/user_management_system/authentication_service/venv/lib/python3.10/site-packages/sqlalchemy/engine/base.py", line 1510, in _handle_dbapi_exception
    util.raise_(
  File "/home/sale/projects/coursework/iep_project/store_management_system/development/user_management_system/authentication_service/venv/lib/python3.10/site-packages/sqlalchemy/util/compat.py", line 182, in raise_
    raise exception
  File "/home/sale/projects/coursework/iep_project/store_management_system/development/user_management_system/authentication_service/venv/lib/python3.10/site-packages/sqlalchemy/engine/base.py", line 1276, in _execute_context
    self.dialect.do_execute(
  File "/home/sale/projects/coursework/iep_project/store_management_system/development/user_management_system/authentication_service/venv/lib/python3.10/site-packages/sqlalchemy/engine/default.py", line 608, in do_execute
    cursor.execute(statement, parameters)
  File "/home/sale/projects/coursework/iep_project/store_management_system/development/user_management_system/authentication_service/venv/lib/python3.10/site-packages/pymysql/cursors.py", line 153, in execute
    result = self._query(query)
  File "/home/sale/projects/coursework/iep_project/store_management_system/development/user_management_system/authentication_service/venv/lib/python3.10/site-packages/pymysql/cursors.py", line 322, in _query
    conn.query(q)
  File "/home/sale/projects/coursework/iep_project/store_management_system/development/user_management_system/authentication_service/venv/lib/python3.10/site-packages/pymysql/connections.py", line 558, in query
    self._affected_rows = self._read_query_result(unbuffered=unbuffered)
  File "/home/sale/projects/coursework/iep_project/store_management_system/development/user_management_system/authentication_service/venv/lib/python3.10/site-packages/pymysql/connections.py", line 822, in _read_query_result
    result.read()
  File "/home/sale/projects/coursework/iep_project/store_management_system/development/user_management_system/authentication_service/venv/lib/python3.10/site-packages/pymysql/connections.py", line 1200, in read
    first_packet = self.connection._read_packet()
  File "/home/sale/projects/coursework/iep_project/store_management_system/development/user_management_system/authentication_service/venv/lib/python3.10/site-packages/pymysql/connections.py", line 772, in _read_packet
    packet.raise_for_error()
  File "/home/sale/projects/coursework/iep_project/store_management_system/development/user_management_system/authentication_service/venv/lib/python3.10/site-packages/pymysql/protocol.py", line 221, in raise_for_error
    err.raise_mysql_exception(self._data)
  File "/home/sale/projects/coursework/iep_project/store_management_system/development/user_management_system/authentication_service/venv/lib/python3.10/site-packages/pymysql/err.py", line 143, in raise_mysql_exception
    raise errorclass(errno, errval)
sqlalchemy.exc.OperationalError: (pymysql.err.OperationalError) (1049, "Unknown database 'authentication'")
[SQL: INSERT INTO users (email, forename, surname, password) VALUES (%(email)s, %(forename)s, %(surname)s, %(password)s)]
[parameters: {'email': 'jane@gmail.com', 'forename': 'Jane', 'surname': 'Doe', 'password': 'aA123456'}]
(Background on this error at: http://sqlalche.me/e/13/e3q8)
2023-08-29 14:13:00 [ERROR] Failed to login
Traceback (most recent call last):
  File "/home/sale/projects/coursework/iep_project/store_management_system/development/user_management_system/authentication_service/venv/lib/python3.10/site-packages/sqlalchemy/engine/base.py", line 1276, in _execute_context
    self.dialect.do_execute(
  File "/home/sale/projects/coursework/iep_project/store_management_system/development/user_management_system/authentication_service/venv/lib/python3.10/site-packages/sqlalchemy/engine/default.py", line 608, in do_execute
    cursor.execute(statement, parameters)
  File "/home/sale/projects/coursework/iep_project/store_management_system/development/user_management_system/authentication_service/venv/lib/python3.10/site-packages/pymysql/cursors.py", line 153, in execute
    result = self._query(query)
  File "/home/sale/projects/coursework/iep_project/store_management_system/development/user_management_system/authentication_service/venv/lib/python3.10/site-packages/pymysql/cursors.py", line 322, in _query
    conn.query(q)
  File "/home/sale/projects/coursework/iep_project/store_management_system/development/user_management_system/authentication_service/venv/lib/python3.10/site-packages/pymysql/connections.py", line 558, in query
    self._affected_rows = self._read_query_result(unbuffered=unbuffered)
  File "/home/sale/projects/coursework/iep_project/store_management_system/development/user_management_system/authentication_service/venv/lib/python3.10/site-packages/pymysql/connections.py", line 822, in _read_query_result
    result.read()
  File "/home/sale/projects/coursework/iep_project/store_management_system/development/user_management_system/authentication_service/venv/lib/python3.10/site-packages/pymysql/connections.py", line 1200, in read
    first_packet = self.connection._read_packet()
  File "/home/sale/projects/coursework/iep_project/store_management_system/development/user_management_system/authentication_service/venv/lib/python3.10/site-packages/pymysql/connections.py", line 772, in _read_packet
    packet.raise_for_error()
  File "/home/sale/projects/coursework/iep_project/store_management_system/development/user_management_system/authentication_service/venv/lib/python3.10/site-packages/pymysql/protocol.py", line 221, in raise_for_error
    err.raise_mysql_exception(self._data)
  File "/home/sale/projects/coursework/iep_project/store_management_system/development/user_management_system/authentication_service/venv/lib/python3.10/site-packages/pymysql/err.py", line 143, in raise_mysql_exception
    raise errorclass(errno, errval)
pymysql.err.OperationalError: (1049, "Unknown database 'authentication'")

The above exception was the direct cause of the following exception:

Traceback (most recent call last):
  File "/home/sale/projects/coursework/iep_project/store_management_system/development/user_management_system/authentication_service/app/blueprints/login.py", line 78, in login_user
    ).first()
  File "/home/sale/projects/coursework/iep_project/store_management_system/development/user_management_system/authentication_service/venv/lib/python3.10/site-packages/sqlalchemy/orm/query.py", line 3429, in first
    ret = list(self[0:1])
  File "/home/sale/projects/coursework/iep_project/store_management_system/development/user_management_system/authentication_service/venv/lib/python3.10/site-packages/sqlalchemy/orm/query.py", line 3203, in __getitem__
    return list(res)
  File "/home/sale/projects/coursework/iep_project/store_management_system/development/user_management_system/authentication_service/venv/lib/python3.10/site-packages/sqlalchemy/orm/query.py", line 3535, in __iter__
    return self._execute_and_instances(context)
  File "/home/sale/projects/coursework/iep_project/store_management_system/development/user_management_system/authentication_service/venv/lib/python3.10/site-packages/sqlalchemy/orm/query.py", line 3560, in _execute_and_instances
    result = conn.execute(querycontext.statement, self._params)
  File "/home/sale/projects/coursework/iep_project/store_management_system/development/user_management_system/authentication_service/venv/lib/python3.10/site-packages/sqlalchemy/engine/base.py", line 1011, in execute
    return meth(self, multiparams, params)
  File "/home/sale/projects/coursework/iep_project/store_management_system/development/user_management_system/authentication_service/venv/lib/python3.10/site-packages/sqlalchemy/sql/elements.py", line 298, in _execute_on_connection
    return connection._execute_clauseelement(self, multiparams, params)
  File "/home/sale/projects/coursework/iep_project/store_management_system/development/user_management_system/authentication_service/venv/lib/python3.10/site-packages/sqlalchemy/engine/base.py", line 1124, in _execute_clauseelement
    ret = self._execute_context(
  File "/home/sale/projects/coursework/iep_project/store_management_system/development/user_management_system/authentication_service/venv/lib/python3.10/site-packages/sqlalchemy/engine/base.py", line 1316, in _execute_context
    self._handle_dbapi_exception(
  File "/home/sale/projects/coursework/iep_project/store_management_system/development/user_management_system/authentication_service/venv/lib/python3.10/site-packages/sqlalchemy/engine/base.py", line 1510, in _handle_dbapi_exception
    util.raise_(
  File "/home/sale/projects/coursework/iep_project/store_management_system/development/user_management_system/authentication_service/venv/lib/python3.10/site-packages/sqlalchemy/util/compat.py", line 182, in raise_
    raise exception
  File "/home/sale/projects/coursework/iep_project/store_management_system/development/user_management_system/authentication_service/venv/lib/python3.10/site-packages/sqlalchemy/engine/base.py", line 1276, in _execute_context
    self.dialect.do_execute(
  File "/home/sale/projects/coursework/iep_project/store_management_system/development/user_management_system/authentication_service/venv/lib/python3.10/site-packages/sqlalchemy/engine/default.py", line 608, in do_execute
    cursor.execute(statement, parameters)
  File "/home/sale/projects/coursework/iep_project/store_management_system/development/user_management_system/authentication_service/venv/lib/python3.10/site-packages/pymysql/cursors.py", line 153, in execute
    result = self._query(query)
  File "/home/sale/projects/coursework/iep_project/store_management_system/development/user_management_system/authentication_service/venv/lib/python3.10/site-packages/pymysql/cursors.py", line 322, in _query
    conn.query(q)
  File "/home/sale/projects/coursework/iep_project/store_management_system/development/user_management_system/authentication_service/venv/lib/python3.10/site-packages/pymysql/connections.py", line 558, in query
    self._affected_rows = self._read_query_result(unbuffered=unbuffered)
  File "/home/sale/projects/coursework/iep_project/store_management_system/development/user_management_system/authentication_service/venv/lib/python3.10/site-packages/pymysql/connections.py", line 822, in _read_query_result
    result.read()
  File "/home/sale/projects/coursework/iep_project/store_management_system/development/user_management_system/authentication_service/venv/lib/python3.10/site-packages/pymysql/connections.py", line 1200, in read
    first_packet = self.connection._read_packet()
  File "/home/sale/projects/coursework/iep_project/store_management_system/development/user_management_system/authentication_service/venv/lib/python3.10/site-packages/pymysql/connections.py", line 772, in _read_packet
    packet.raise_for_error()
  File "/home/sale/projects/coursework/iep_project/store_management_system/development/user_management_system/authentication_service/venv/lib/python3.10/site-packages/pymysql/protocol.py", line 221, in raise_for_error
    err.raise_mysql_exception(self._data)
  File "/home/sale/projects/coursework/iep_project/store_management_system/development/user_management_system/authentication_service/venv/lib/python3.10/site-packages/pymysql/err.py", line 143, in raise_mysql_exception
    raise errorclass(errno, errval)
sqlalchemy.exc.OperationalError: (pymysql.err.OperationalError) (1049, "Unknown database 'authentication'")
[SQL: SELECT users.id AS users_id, users.email AS users_email, users.forename AS users_forename, users.surname AS users_surname, users.password AS users_password 
FROM users 
WHERE users.email = %(email_1)s AND users.password = %(password_1)s 
 LIMIT %(param_1)s]
[parameters: {'email_1': 'onlymoney@gmail.com', 'password_1': 'evenmoremoney', 'param_1': 1}]
(Background on this error at: http://sqlalche.me/e/13/e3q8)
2023-08-29 14:13:00 [ERROR] Failed to login
Traceback (most recent call last):
  File "/home/sale/projects/coursework/iep_project/store_management_system/development/user_management_system/authentication_service/venv/lib/python3.10/site-packages/sqlalchemy/engine/base.py", line 1276, in _execute_context
    self.dialect.do_execute(
  File "/home/sale/projects/coursework/iep_project/store_management_system/development/user_management_system/authentication_service/venv/lib/python3.10/site-packages/sqlalchemy/engine/default.py", line 608, in do_execute
    cursor.execute(statement, parameters)
  File "/home/sale/projects/coursework/iep_project/store_management_system/development/user_management_system/authentication_service/venv/lib/python3.10/site-packages/pymysql/cursors.py", line 153, in execute
    result = self._query(query)
  File "/home/sale/projects/coursework/iep_project/store_management_system/development/user_management_system/authentication_service/venv/lib/python3.10/site-packages/pymysql/cursors.py", line 322, in _query
    conn.query(q)
  File "/home/sale/projects/coursework/iep_project/store_management_system/development/user_management_system/authentication_service/venv/lib/python3.10/site-packages/pymysql/connections.py", line 558, in query
    self._affected_rows = self._read_query_result(unbuffered=unbuffered)
  File "/home/sale/projects/coursework/iep_project/store_management_system/development/user_management_system/authentication_service/venv/lib/python3.10/site-packages/pymysql/connections.py", line 822, in _read_query_result
    result.read()
  File "/home/sale/projects/coursework/iep_project/store_management_system/development/user_management_system/authentication_service/venv/lib/python3.10/site-packages/pymysql/connections.py", line 1200, in read
    first_packet = self.connection._read_packet()
  File "/home/sale/projects/coursework/iep_project/store_management_system/development/user_management_system/authentication_service/venv/lib/python3.10/site-packages/pymysql/connections.py", line 772, in _read_packet
    packet.raise_for_error()
  File "/home/sale/projects/coursework/iep_project/store_management_system/development/user_management_system/authentication_service/venv/lib/python3.10/site-packages/pymysql/protocol.py", line 221, in raise_for_error
    err.raise_mysql_exception(self._data)
  File "/home/sale/projects/coursework/iep_project/store_management_system/development/user_management_system/authentication_service/venv/lib/python3.10/site-packages/pymysql/err.py", line 143, in raise_mysql_exception
    raise errorclass(errno, errval)
pymysql.err.OperationalError: (1049, "Unknown database 'authentication'")

The above exception was the direct cause of the following exception:

Traceback (most recent call last):
  File "/home/sale/projects/coursework/iep_project/store_management_system/development/user_management_system/authentication_service/app/blueprints/login.py", line 78, in login_user
    ).first()
  File "/home/sale/projects/coursework/iep_project/store_management_system/development/user_management_system/authentication_service/venv/lib/python3.10/site-packages/sqlalchemy/orm/query.py", line 3429, in first
    ret = list(self[0:1])
  File "/home/sale/projects/coursework/iep_project/store_management_system/development/user_management_system/authentication_service/venv/lib/python3.10/site-packages/sqlalchemy/orm/query.py", line 3203, in __getitem__
    return list(res)
  File "/home/sale/projects/coursework/iep_project/store_management_system/development/user_management_system/authentication_service/venv/lib/python3.10/site-packages/sqlalchemy/orm/query.py", line 3535, in __iter__
    return self._execute_and_instances(context)
  File "/home/sale/projects/coursework/iep_project/store_management_system/development/user_management_system/authentication_service/venv/lib/python3.10/site-packages/sqlalchemy/orm/query.py", line 3560, in _execute_and_instances
    result = conn.execute(querycontext.statement, self._params)
  File "/home/sale/projects/coursework/iep_project/store_management_system/development/user_management_system/authentication_service/venv/lib/python3.10/site-packages/sqlalchemy/engine/base.py", line 1011, in execute
    return meth(self, multiparams, params)
  File "/home/sale/projects/coursework/iep_project/store_management_system/development/user_management_system/authentication_service/venv/lib/python3.10/site-packages/sqlalchemy/sql/elements.py", line 298, in _execute_on_connection
    return connection._execute_clauseelement(self, multiparams, params)
  File "/home/sale/projects/coursework/iep_project/store_management_system/development/user_management_system/authentication_service/venv/lib/python3.10/site-packages/sqlalchemy/engine/base.py", line 1124, in _execute_clauseelement
    ret = self._execute_context(
  File "/home/sale/projects/coursework/iep_project/store_management_system/development/user_management_system/authentication_service/venv/lib/python3.10/site-packages/sqlalchemy/engine/base.py", line 1316, in _execute_context
    self._handle_dbapi_exception(
  File "/home/sale/projects/coursework/iep_project/store_management_system/development/user_management_system/authentication_service/venv/lib/python3.10/site-packages/sqlalchemy/engine/base.py", line 1510, in _handle_dbapi_exception
    util.raise_(
  File "/home/sale/projects/coursework/iep_project/store_management_system/development/user_management_system/authentication_service/venv/lib/python3.10/site-packages/sqlalchemy/util/compat.py", line 182, in raise_
    raise exception
  File "/home/sale/projects/coursework/iep_project/store_management_system/development/user_management_system/authentication_service/venv/lib/python3.10/site-packages/sqlalchemy/engine/base.py", line 1276, in _execute_context
    self.dialect.do_execute(
  File "/home/sale/projects/coursework/iep_project/store_management_system/development/user_management_system/authentication_service/venv/lib/python3.10/site-packages/sqlalchemy/engine/default.py", line 608, in do_execute
    cursor.execute(statement, parameters)
  File "/home/sale/projects/coursework/iep_project/store_management_system/development/user_management_system/authentication_service/venv/lib/python3.10/site-packages/pymysql/cursors.py", line 153, in execute
    result = self._query(query)
  File "/home/sale/projects/coursework/iep_project/store_management_system/development/user_management_system/authentication_service/venv/lib/python3.10/site-packages/pymysql/cursors.py", line 322, in _query
    conn.query(q)
  File "/home/sale/projects/coursework/iep_project/store_management_system/development/user_management_system/authentication_service/venv/lib/python3.10/site-packages/pymysql/connections.py", line 558, in query
    self._affected_rows = self._read_query_result(unbuffered=unbuffered)
  File "/home/sale/projects/coursework/iep_project/store_management_system/development/user_management_system/authentication_service/venv/lib/python3.10/site-packages/pymysql/connections.py", line 822, in _read_query_result
    result.read()
  File "/home/sale/projects/coursework/iep_project/store_management_system/development/user_management_system/authentication_service/venv/lib/python3.10/site-packages/pymysql/connections.py", line 1200, in read
    first_packet = self.connection._read_packet()
  File "/home/sale/projects/coursework/iep_project/store_management_system/development/user_management_system/authentication_service/venv/lib/python3.10/site-packages/pymysql/connections.py", line 772, in _read_packet
    packet.raise_for_error()
  File "/home/sale/projects/coursework/iep_project/store_management_system/development/user_management_system/authentication_service/venv/lib/python3.10/site-packages/pymysql/protocol.py", line 221, in raise_for_error
    err.raise_mysql_exception(self._data)
  File "/home/sale/projects/coursework/iep_project/store_management_system/development/user_management_system/authentication_service/venv/lib/python3.10/site-packages/pymysql/err.py", line 143, in raise_mysql_exception
    raise errorclass(errno, errval)
sqlalchemy.exc.OperationalError: (pymysql.err.OperationalError) (1049, "Unknown database 'authentication'")
[SQL: SELECT users.id AS users_id, users.email AS users_email, users.forename AS users_forename, users.surname AS users_surname, users.password AS users_password 
FROM users 
WHERE users.email = %(email_1)s AND users.password = %(password_1)s 
 LIMIT %(param_1)s]
[parameters: {'email_1': 'jane@gmail.com', 'password_1': 'aA123456', 'param_1': 1}]
(Background on this error at: http://sqlalche.me/e/13/e3q8)
2023-08-29 14:13:00 [ERROR] Failed to login
Traceback (most recent call last):
  File "/home/sale/projects/coursework/iep_project/store_management_system/development/user_management_system/authentication_service/venv/lib/python3.10/site-packages/sqlalchemy/engine/base.py", line 1276, in _execute_context
    self.dialect.do_execute(
  File "/home/sale/projects/coursework/iep_project/store_management_system/development/user_management_system/authentication_service/venv/lib/python3.10/site-packages/sqlalchemy/engine/default.py", line 608, in do_execute
    cursor.execute(statement, parameters)
  File "/home/sale/projects/coursework/iep_project/store_management_system/development/user_management_system/authentication_service/venv/lib/python3.10/site-packages/pymysql/cursors.py", line 153, in execute
    result = self._query(query)
  File "/home/sale/projects/coursework/iep_project/store_management_system/development/user_management_system/authentication_service/venv/lib/python3.10/site-packages/pymysql/cursors.py", line 322, in _query
    conn.query(q)
  File "/home/sale/projects/coursework/iep_project/store_management_system/development/user_management_system/authentication_service/venv/lib/python3.10/site-packages/pymysql/connections.py", line 558, in query
    self._affected_rows = self._read_query_result(unbuffered=unbuffered)
  File "/home/sale/projects/coursework/iep_project/store_management_system/development/user_management_system/authentication_service/venv/lib/python3.10/site-packages/pymysql/connections.py", line 822, in _read_query_result
    result.read()
  File "/home/sale/projects/coursework/iep_project/store_management_system/development/user_management_system/authentication_service/venv/lib/python3.10/site-packages/pymysql/connections.py", line 1200, in read
    first_packet = self.connection._read_packet()
  File "/home/sale/projects/coursework/iep_project/store_management_system/development/user_management_system/authentication_service/venv/lib/python3.10/site-packages/pymysql/connections.py", line 772, in _read_packet
    packet.raise_for_error()
  File "/home/sale/projects/coursework/iep_project/store_management_system/development/user_management_system/authentication_service/venv/lib/python3.10/site-packages/pymysql/protocol.py", line 221, in raise_for_error
    err.raise_mysql_exception(self._data)
  File "/home/sale/projects/coursework/iep_project/store_management_system/development/user_management_system/authentication_service/venv/lib/python3.10/site-packages/pymysql/err.py", line 143, in raise_mysql_exception
    raise errorclass(errno, errval)
pymysql.err.OperationalError: (1049, "Unknown database 'authentication'")

The above exception was the direct cause of the following exception:

Traceback (most recent call last):
  File "/home/sale/projects/coursework/iep_project/store_management_system/development/user_management_system/authentication_service/app/blueprints/login.py", line 78, in login_user
    ).first()
  File "/home/sale/projects/coursework/iep_project/store_management_system/development/user_management_system/authentication_service/venv/lib/python3.10/site-packages/sqlalchemy/orm/query.py", line 3429, in first
    ret = list(self[0:1])
  File "/home/sale/projects/coursework/iep_project/store_management_system/development/user_management_system/authentication_service/venv/lib/python3.10/site-packages/sqlalchemy/orm/query.py", line 3203, in __getitem__
    return list(res)
  File "/home/sale/projects/coursework/iep_project/store_management_system/development/user_management_system/authentication_service/venv/lib/python3.10/site-packages/sqlalchemy/orm/query.py", line 3535, in __iter__
    return self._execute_and_instances(context)
  File "/home/sale/projects/coursework/iep_project/store_management_system/development/user_management_system/authentication_service/venv/lib/python3.10/site-packages/sqlalchemy/orm/query.py", line 3560, in _execute_and_instances
    result = conn.execute(querycontext.statement, self._params)
  File "/home/sale/projects/coursework/iep_project/store_management_system/development/user_management_system/authentication_service/venv/lib/python3.10/site-packages/sqlalchemy/engine/base.py", line 1011, in execute
    return meth(self, multiparams, params)
  File "/home/sale/projects/coursework/iep_project/store_management_system/development/user_management_system/authentication_service/venv/lib/python3.10/site-packages/sqlalchemy/sql/elements.py", line 298, in _execute_on_connection
    return connection._execute_clauseelement(self, multiparams, params)
  File "/home/sale/projects/coursework/iep_project/store_management_system/development/user_management_system/authentication_service/venv/lib/python3.10/site-packages/sqlalchemy/engine/base.py", line 1124, in _execute_clauseelement
    ret = self._execute_context(
  File "/home/sale/projects/coursework/iep_project/store_management_system/development/user_management_system/authentication_service/venv/lib/python3.10/site-packages/sqlalchemy/engine/base.py", line 1316, in _execute_context
    self._handle_dbapi_exception(
  File "/home/sale/projects/coursework/iep_project/store_management_system/development/user_management_system/authentication_service/venv/lib/python3.10/site-packages/sqlalchemy/engine/base.py", line 1510, in _handle_dbapi_exception
    util.raise_(
  File "/home/sale/projects/coursework/iep_project/store_management_system/development/user_management_system/authentication_service/venv/lib/python3.10/site-packages/sqlalchemy/util/compat.py", line 182, in raise_
    raise exception
  File "/home/sale/projects/coursework/iep_project/store_management_system/development/user_management_system/authentication_service/venv/lib/python3.10/site-packages/sqlalchemy/engine/base.py", line 1276, in _execute_context
    self.dialect.do_execute(
  File "/home/sale/projects/coursework/iep_project/store_management_system/development/user_management_system/authentication_service/venv/lib/python3.10/site-packages/sqlalchemy/engine/default.py", line 608, in do_execute
    cursor.execute(statement, parameters)
  File "/home/sale/projects/coursework/iep_project/store_management_system/development/user_management_system/authentication_service/venv/lib/python3.10/site-packages/pymysql/cursors.py", line 153, in execute
    result = self._query(query)
  File "/home/sale/projects/coursework/iep_project/store_management_system/development/user_management_system/authentication_service/venv/lib/python3.10/site-packages/pymysql/cursors.py", line 322, in _query
    conn.query(q)
  File "/home/sale/projects/coursework/iep_project/store_management_system/development/user_management_system/authentication_service/venv/lib/python3.10/site-packages/pymysql/connections.py", line 558, in query
    self._affected_rows = self._read_query_result(unbuffered=unbuffered)
  File "/home/sale/projects/coursework/iep_project/store_management_system/development/user_management_system/authentication_service/venv/lib/python3.10/site-packages/pymysql/connections.py", line 822, in _read_query_result
    result.read()
  File "/home/sale/projects/coursework/iep_project/store_management_system/development/user_management_system/authentication_service/venv/lib/python3.10/site-packages/pymysql/connections.py", line 1200, in read
    first_packet = self.connection._read_packet()
  File "/home/sale/projects/coursework/iep_project/store_management_system/development/user_management_system/authentication_service/venv/lib/python3.10/site-packages/pymysql/connections.py", line 772, in _read_packet
    packet.raise_for_error()
  File "/home/sale/projects/coursework/iep_project/store_management_system/development/user_management_system/authentication_service/venv/lib/python3.10/site-packages/pymysql/protocol.py", line 221, in raise_for_error
    err.raise_mysql_exception(self._data)
  File "/home/sale/projects/coursework/iep_project/store_management_system/development/user_management_system/authentication_service/venv/lib/python3.10/site-packages/pymysql/err.py", line 143, in raise_mysql_exception
    raise errorclass(errno, errval)
sqlalchemy.exc.OperationalError: (pymysql.err.OperationalError) (1049, "Unknown database 'authentication'")
[SQL: SELECT users.id AS users_id, users.email AS users_email, users.forename AS users_forename, users.surname AS users_surname, users.password AS users_password 
FROM users 
WHERE users.email = %(email_1)s AND users.password = %(password_1)s 
 LIMIT %(param_1)s]
[parameters: {'email_1': 'john@gmail.com', 'password_1': 'aA123456', 'param_1': 1}]
(Background on this error at: http://sqlalche.me/e/13/e3q8)
2023-08-29 14:13:00 [ERROR] Failed to register courier
Traceback (most recent call last):
  File "/home/sale/projects/coursework/iep_project/store_management_system/development/user_management_system/authentication_service/venv/lib/python3.10/site-packages/sqlalchemy/engine/base.py", line 1276, in _execute_context
    self.dialect.do_execute(
  File "/home/sale/projects/coursework/iep_project/store_management_system/development/user_management_system/authentication_service/venv/lib/python3.10/site-packages/sqlalchemy/engine/default.py", line 608, in do_execute
    cursor.execute(statement, parameters)
  File "/home/sale/projects/coursework/iep_project/store_management_system/development/user_management_system/authentication_service/venv/lib/python3.10/site-packages/pymysql/cursors.py", line 153, in execute
    result = self._query(query)
  File "/home/sale/projects/coursework/iep_project/store_management_system/development/user_management_system/authentication_service/venv/lib/python3.10/site-packages/pymysql/cursors.py", line 322, in _query
    conn.query(q)
  File "/home/sale/projects/coursework/iep_project/store_management_system/development/user_management_system/authentication_service/venv/lib/python3.10/site-packages/pymysql/connections.py", line 558, in query
    self._affected_rows = self._read_query_result(unbuffered=unbuffered)
  File "/home/sale/projects/coursework/iep_project/store_management_system/development/user_management_system/authentication_service/venv/lib/python3.10/site-packages/pymysql/connections.py", line 822, in _read_query_result
    result.read()
  File "/home/sale/projects/coursework/iep_project/store_management_system/development/user_management_system/authentication_service/venv/lib/python3.10/site-packages/pymysql/connections.py", line 1200, in read
    first_packet = self.connection._read_packet()
  File "/home/sale/projects/coursework/iep_project/store_management_system/development/user_management_system/authentication_service/venv/lib/python3.10/site-packages/pymysql/connections.py", line 772, in _read_packet
    packet.raise_for_error()
  File "/home/sale/projects/coursework/iep_project/store_management_system/development/user_management_system/authentication_service/venv/lib/python3.10/site-packages/pymysql/protocol.py", line 221, in raise_for_error
    err.raise_mysql_exception(self._data)
  File "/home/sale/projects/coursework/iep_project/store_management_system/development/user_management_system/authentication_service/venv/lib/python3.10/site-packages/pymysql/err.py", line 143, in raise_mysql_exception
    raise errorclass(errno, errval)
pymysql.err.OperationalError: (1049, "Unknown database 'authentication'")

The above exception was the direct cause of the following exception:

Traceback (most recent call last):
  File "/home/sale/projects/coursework/iep_project/store_management_system/development/user_management_system/authentication_service/app/blueprints/register.py", line 100, in register_user_view
    raise e
  File "/home/sale/projects/coursework/iep_project/store_management_system/development/user_management_system/authentication_service/app/blueprints/register.py", line 87, in register_user_view
    db.session.flush()
  File "/home/sale/projects/coursework/iep_project/store_management_system/development/user_management_system/authentication_service/venv/lib/python3.10/site-packages/sqlalchemy/orm/scoping.py", line 163, in do
    return getattr(self.registry(), name)(*args, **kwargs)
  File "/home/sale/projects/coursework/iep_project/store_management_system/development/user_management_system/authentication_service/venv/lib/python3.10/site-packages/sqlalchemy/orm/session.py", line 2540, in flush
    self._flush(objects)
  File "/home/sale/projects/coursework/iep_project/store_management_system/development/user_management_system/authentication_service/venv/lib/python3.10/site-packages/sqlalchemy/orm/session.py", line 2681, in _flush
    with util.safe_reraise():
  File "/home/sale/projects/coursework/iep_project/store_management_system/development/user_management_system/authentication_service/venv/lib/python3.10/site-packages/sqlalchemy/util/langhelpers.py", line 68, in __exit__
    compat.raise_(
  File "/home/sale/projects/coursework/iep_project/store_management_system/development/user_management_system/authentication_service/venv/lib/python3.10/site-packages/sqlalchemy/util/compat.py", line 182, in raise_
    raise exception
  File "/home/sale/projects/coursework/iep_project/store_management_system/development/user_management_system/authentication_service/venv/lib/python3.10/site-packages/sqlalchemy/orm/session.py", line 2642, in _flush
    flush_context.execute()
  File "/home/sale/projects/coursework/iep_project/store_management_system/development/user_management_system/authentication_service/venv/lib/python3.10/site-packages/sqlalchemy/orm/unitofwork.py", line 422, in execute
    rec.execute(self)
  File "/home/sale/projects/coursework/iep_project/store_management_system/development/user_management_system/authentication_service/venv/lib/python3.10/site-packages/sqlalchemy/orm/unitofwork.py", line 586, in execute
    persistence.save_obj(
  File "/home/sale/projects/coursework/iep_project/store_management_system/development/user_management_system/authentication_service/venv/lib/python3.10/site-packages/sqlalchemy/orm/persistence.py", line 239, in save_obj
    _emit_insert_statements(
  File "/home/sale/projects/coursework/iep_project/store_management_system/development/user_management_system/authentication_service/venv/lib/python3.10/site-packages/sqlalchemy/orm/persistence.py", line 1135, in _emit_insert_statements
    result = cached_connections[connection].execute(
  File "/home/sale/projects/coursework/iep_project/store_management_system/development/user_management_system/authentication_service/venv/lib/python3.10/site-packages/sqlalchemy/engine/base.py", line 1011, in execute
    return meth(self, multiparams, params)
  File "/home/sale/projects/coursework/iep_project/store_management_system/development/user_management_system/authentication_service/venv/lib/python3.10/site-packages/sqlalchemy/sql/elements.py", line 298, in _execute_on_connection
    return connection._execute_clauseelement(self, multiparams, params)
  File "/home/sale/projects/coursework/iep_project/store_management_system/development/user_management_system/authentication_service/venv/lib/python3.10/site-packages/sqlalchemy/engine/base.py", line 1124, in _execute_clauseelement
    ret = self._execute_context(
  File "/home/sale/projects/coursework/iep_project/store_management_system/development/user_management_system/authentication_service/venv/lib/python3.10/site-packages/sqlalchemy/engine/base.py", line 1316, in _execute_context
    self._handle_dbapi_exception(
  File "/home/sale/projects/coursework/iep_project/store_management_system/development/user_management_system/authentication_service/venv/lib/python3.10/site-packages/sqlalchemy/engine/base.py", line 1510, in _handle_dbapi_exception
    util.raise_(
  File "/home/sale/projects/coursework/iep_project/store_management_system/development/user_management_system/authentication_service/venv/lib/python3.10/site-packages/sqlalchemy/util/compat.py", line 182, in raise_
    raise exception
  File "/home/sale/projects/coursework/iep_project/store_management_system/development/user_management_system/authentication_service/venv/lib/python3.10/site-packages/sqlalchemy/engine/base.py", line 1276, in _execute_context
    self.dialect.do_execute(
  File "/home/sale/projects/coursework/iep_project/store_management_system/development/user_management_system/authentication_service/venv/lib/python3.10/site-packages/sqlalchemy/engine/default.py", line 608, in do_execute
    cursor.execute(statement, parameters)
  File "/home/sale/projects/coursework/iep_project/store_management_system/development/user_management_system/authentication_service/venv/lib/python3.10/site-packages/pymysql/cursors.py", line 153, in execute
    result = self._query(query)
  File "/home/sale/projects/coursework/iep_project/store_management_system/development/user_management_system/authentication_service/venv/lib/python3.10/site-packages/pymysql/cursors.py", line 322, in _query
    conn.query(q)
  File "/home/sale/projects/coursework/iep_project/store_management_system/development/user_management_system/authentication_service/venv/lib/python3.10/site-packages/pymysql/connections.py", line 558, in query
    self._affected_rows = self._read_query_result(unbuffered=unbuffered)
  File "/home/sale/projects/coursework/iep_project/store_management_system/development/user_management_system/authentication_service/venv/lib/python3.10/site-packages/pymysql/connections.py", line 822, in _read_query_result
    result.read()
  File "/home/sale/projects/coursework/iep_project/store_management_system/development/user_management_system/authentication_service/venv/lib/python3.10/site-packages/pymysql/connections.py", line 1200, in read
    first_packet = self.connection._read_packet()
  File "/home/sale/projects/coursework/iep_project/store_management_system/development/user_management_system/authentication_service/venv/lib/python3.10/site-packages/pymysql/connections.py", line 772, in _read_packet
    packet.raise_for_error()
  File "/home/sale/projects/coursework/iep_project/store_management_system/development/user_management_system/authentication_service/venv/lib/python3.10/site-packages/pymysql/protocol.py", line 221, in raise_for_error
    err.raise_mysql_exception(self._data)
  File "/home/sale/projects/coursework/iep_project/store_management_system/development/user_management_system/authentication_service/venv/lib/python3.10/site-packages/pymysql/err.py", line 143, in raise_mysql_exception
    raise errorclass(errno, errval)
sqlalchemy.exc.OperationalError: (pymysql.err.OperationalError) (1049, "Unknown database 'authentication'")
[SQL: INSERT INTO users (email, forename, surname, password) VALUES (%(email)s, %(forename)s, %(surname)s, %(password)s)]
[parameters: {'email': 'john@gmail.com', 'forename': 'John', 'surname': 'Doe', 'password': 'aA123456'}]
(Background on this error at: http://sqlalche.me/e/13/e3q8)
2023-08-29 14:13:00 [ERROR] Failed to login
Traceback (most recent call last):
  File "/home/sale/projects/coursework/iep_project/store_management_system/development/user_management_system/authentication_service/venv/lib/python3.10/site-packages/sqlalchemy/engine/base.py", line 1276, in _execute_context
    self.dialect.do_execute(
  File "/home/sale/projects/coursework/iep_project/store_management_system/development/user_management_system/authentication_service/venv/lib/python3.10/site-packages/sqlalchemy/engine/default.py", line 608, in do_execute
    cursor.execute(statement, parameters)
  File "/home/sale/projects/coursework/iep_project/store_management_system/development/user_management_system/authentication_service/venv/lib/python3.10/site-packages/pymysql/cursors.py", line 153, in execute
    result = self._query(query)
  File "/home/sale/projects/coursework/iep_project/store_management_system/development/user_management_system/authentication_service/venv/lib/python3.10/site-packages/pymysql/cursors.py", line 322, in _query
    conn.query(q)
  File "/home/sale/projects/coursework/iep_project/store_management_system/development/user_management_system/authentication_service/venv/lib/python3.10/site-packages/pymysql/connections.py", line 558, in query
    self._affected_rows = self._read_query_result(unbuffered=unbuffered)
  File "/home/sale/projects/coursework/iep_project/store_management_system/development/user_management_system/authentication_service/venv/lib/python3.10/site-packages/pymysql/connections.py", line 822, in _read_query_result
    result.read()
  File "/home/sale/projects/coursework/iep_project/store_management_system/development/user_management_system/authentication_service/venv/lib/python3.10/site-packages/pymysql/connections.py", line 1200, in read
    first_packet = self.connection._read_packet()
  File "/home/sale/projects/coursework/iep_project/store_management_system/development/user_management_system/authentication_service/venv/lib/python3.10/site-packages/pymysql/connections.py", line 772, in _read_packet
    packet.raise_for_error()
  File "/home/sale/projects/coursework/iep_project/store_management_system/development/user_management_system/authentication_service/venv/lib/python3.10/site-packages/pymysql/protocol.py", line 221, in raise_for_error
    err.raise_mysql_exception(self._data)
  File "/home/sale/projects/coursework/iep_project/store_management_system/development/user_management_system/authentication_service/venv/lib/python3.10/site-packages/pymysql/err.py", line 143, in raise_mysql_exception
    raise errorclass(errno, errval)
pymysql.err.OperationalError: (1049, "Unknown database 'authentication'")

The above exception was the direct cause of the following exception:

Traceback (most recent call last):
  File "/home/sale/projects/coursework/iep_project/store_management_system/development/user_management_system/authentication_service/app/blueprints/login.py", line 78, in login_user
    ).first()
  File "/home/sale/projects/coursework/iep_project/store_management_system/development/user_management_system/authentication_service/venv/lib/python3.10/site-packages/sqlalchemy/orm/query.py", line 3429, in first
    ret = list(self[0:1])
  File "/home/sale/projects/coursework/iep_project/store_management_system/development/user_management_system/authentication_service/venv/lib/python3.10/site-packages/sqlalchemy/orm/query.py", line 3203, in __getitem__
    return list(res)
  File "/home/sale/projects/coursework/iep_project/store_management_system/development/user_management_system/authentication_service/venv/lib/python3.10/site-packages/sqlalchemy/orm/query.py", line 3535, in __iter__
    return self._execute_and_instances(context)
  File "/home/sale/projects/coursework/iep_project/store_management_system/development/user_management_system/authentication_service/venv/lib/python3.10/site-packages/sqlalchemy/orm/query.py", line 3560, in _execute_and_instances
    result = conn.execute(querycontext.statement, self._params)
  File "/home/sale/projects/coursework/iep_project/store_management_system/development/user_management_system/authentication_service/venv/lib/python3.10/site-packages/sqlalchemy/engine/base.py", line 1011, in execute
    return meth(self, multiparams, params)
  File "/home/sale/projects/coursework/iep_project/store_management_system/development/user_management_system/authentication_service/venv/lib/python3.10/site-packages/sqlalchemy/sql/elements.py", line 298, in _execute_on_connection
    return connection._execute_clauseelement(self, multiparams, params)
  File "/home/sale/projects/coursework/iep_project/store_management_system/development/user_management_system/authentication_service/venv/lib/python3.10/site-packages/sqlalchemy/engine/base.py", line 1124, in _execute_clauseelement
    ret = self._execute_context(
  File "/home/sale/projects/coursework/iep_project/store_management_system/development/user_management_system/authentication_service/venv/lib/python3.10/site-packages/sqlalchemy/engine/base.py", line 1316, in _execute_context
    self._handle_dbapi_exception(
  File "/home/sale/projects/coursework/iep_project/store_management_system/development/user_management_system/authentication_service/venv/lib/python3.10/site-packages/sqlalchemy/engine/base.py", line 1510, in _handle_dbapi_exception
    util.raise_(
  File "/home/sale/projects/coursework/iep_project/store_management_system/development/user_management_system/authentication_service/venv/lib/python3.10/site-packages/sqlalchemy/util/compat.py", line 182, in raise_
    raise exception
  File "/home/sale/projects/coursework/iep_project/store_management_system/development/user_management_system/authentication_service/venv/lib/python3.10/site-packages/sqlalchemy/engine/base.py", line 1276, in _execute_context
    self.dialect.do_execute(
  File "/home/sale/projects/coursework/iep_project/store_management_system/development/user_management_system/authentication_service/venv/lib/python3.10/site-packages/sqlalchemy/engine/default.py", line 608, in do_execute
    cursor.execute(statement, parameters)
  File "/home/sale/projects/coursework/iep_project/store_management_system/development/user_management_system/authentication_service/venv/lib/python3.10/site-packages/pymysql/cursors.py", line 153, in execute
    result = self._query(query)
  File "/home/sale/projects/coursework/iep_project/store_management_system/development/user_management_system/authentication_service/venv/lib/python3.10/site-packages/pymysql/cursors.py", line 322, in _query
    conn.query(q)
  File "/home/sale/projects/coursework/iep_project/store_management_system/development/user_management_system/authentication_service/venv/lib/python3.10/site-packages/pymysql/connections.py", line 558, in query
    self._affected_rows = self._read_query_result(unbuffered=unbuffered)
  File "/home/sale/projects/coursework/iep_project/store_management_system/development/user_management_system/authentication_service/venv/lib/python3.10/site-packages/pymysql/connections.py", line 822, in _read_query_result
    result.read()
  File "/home/sale/projects/coursework/iep_project/store_management_system/development/user_management_system/authentication_service/venv/lib/python3.10/site-packages/pymysql/connections.py", line 1200, in read
    first_packet = self.connection._read_packet()
  File "/home/sale/projects/coursework/iep_project/store_management_system/development/user_management_system/authentication_service/venv/lib/python3.10/site-packages/pymysql/connections.py", line 772, in _read_packet
    packet.raise_for_error()
  File "/home/sale/projects/coursework/iep_project/store_management_system/development/user_management_system/authentication_service/venv/lib/python3.10/site-packages/pymysql/protocol.py", line 221, in raise_for_error
    err.raise_mysql_exception(self._data)
  File "/home/sale/projects/coursework/iep_project/store_management_system/development/user_management_system/authentication_service/venv/lib/python3.10/site-packages/pymysql/err.py", line 143, in raise_mysql_exception
    raise errorclass(errno, errval)
sqlalchemy.exc.OperationalError: (pymysql.err.OperationalError) (1049, "Unknown database 'authentication'")
[SQL: SELECT users.id AS users_id, users.email AS users_email, users.forename AS users_forename, users.surname AS users_surname, users.password AS users_password 
FROM users 
WHERE users.email = %(email_1)s AND users.password = %(password_1)s 
 LIMIT %(param_1)s]
[parameters: {'email_1': 'john@gmail.com', 'password_1': 'aA123456', 'param_1': 1}]
(Background on this error at: http://sqlalche.me/e/13/e3q8)
2023-08-29 14:13:00 [ERROR] Failed to register customer
Traceback (most recent call last):
  File "/home/sale/projects/coursework/iep_project/store_management_system/development/user_management_system/authentication_service/venv/lib/python3.10/site-packages/sqlalchemy/engine/base.py", line 1276, in _execute_context
    self.dialect.do_execute(
  File "/home/sale/projects/coursework/iep_project/store_management_system/development/user_management_system/authentication_service/venv/lib/python3.10/site-packages/sqlalchemy/engine/default.py", line 608, in do_execute
    cursor.execute(statement, parameters)
  File "/home/sale/projects/coursework/iep_project/store_management_system/development/user_management_system/authentication_service/venv/lib/python3.10/site-packages/pymysql/cursors.py", line 153, in execute
    result = self._query(query)
  File "/home/sale/projects/coursework/iep_project/store_management_system/development/user_management_system/authentication_service/venv/lib/python3.10/site-packages/pymysql/cursors.py", line 322, in _query
    conn.query(q)
  File "/home/sale/projects/coursework/iep_project/store_management_system/development/user_management_system/authentication_service/venv/lib/python3.10/site-packages/pymysql/connections.py", line 558, in query
    self._affected_rows = self._read_query_result(unbuffered=unbuffered)
  File "/home/sale/projects/coursework/iep_project/store_management_system/development/user_management_system/authentication_service/venv/lib/python3.10/site-packages/pymysql/connections.py", line 822, in _read_query_result
    result.read()
  File "/home/sale/projects/coursework/iep_project/store_management_system/development/user_management_system/authentication_service/venv/lib/python3.10/site-packages/pymysql/connections.py", line 1200, in read
    first_packet = self.connection._read_packet()
  File "/home/sale/projects/coursework/iep_project/store_management_system/development/user_management_system/authentication_service/venv/lib/python3.10/site-packages/pymysql/connections.py", line 772, in _read_packet
    packet.raise_for_error()
  File "/home/sale/projects/coursework/iep_project/store_management_system/development/user_management_system/authentication_service/venv/lib/python3.10/site-packages/pymysql/protocol.py", line 221, in raise_for_error
    err.raise_mysql_exception(self._data)
  File "/home/sale/projects/coursework/iep_project/store_management_system/development/user_management_system/authentication_service/venv/lib/python3.10/site-packages/pymysql/err.py", line 143, in raise_mysql_exception
    raise errorclass(errno, errval)
pymysql.err.OperationalError: (1049, "Unknown database 'authentication'")

The above exception was the direct cause of the following exception:

Traceback (most recent call last):
  File "/home/sale/projects/coursework/iep_project/store_management_system/development/user_management_system/authentication_service/app/blueprints/register.py", line 100, in register_user_view
    raise e
  File "/home/sale/projects/coursework/iep_project/store_management_system/development/user_management_system/authentication_service/app/blueprints/register.py", line 87, in register_user_view
    db.session.flush()
  File "/home/sale/projects/coursework/iep_project/store_management_system/development/user_management_system/authentication_service/venv/lib/python3.10/site-packages/sqlalchemy/orm/scoping.py", line 163, in do
    return getattr(self.registry(), name)(*args, **kwargs)
  File "/home/sale/projects/coursework/iep_project/store_management_system/development/user_management_system/authentication_service/venv/lib/python3.10/site-packages/sqlalchemy/orm/session.py", line 2540, in flush
    self._flush(objects)
  File "/home/sale/projects/coursework/iep_project/store_management_system/development/user_management_system/authentication_service/venv/lib/python3.10/site-packages/sqlalchemy/orm/session.py", line 2681, in _flush
    with util.safe_reraise():
  File "/home/sale/projects/coursework/iep_project/store_management_system/development/user_management_system/authentication_service/venv/lib/python3.10/site-packages/sqlalchemy/util/langhelpers.py", line 68, in __exit__
    compat.raise_(
  File "/home/sale/projects/coursework/iep_project/store_management_system/development/user_management_system/authentication_service/venv/lib/python3.10/site-packages/sqlalchemy/util/compat.py", line 182, in raise_
    raise exception
  File "/home/sale/projects/coursework/iep_project/store_management_system/development/user_management_system/authentication_service/venv/lib/python3.10/site-packages/sqlalchemy/orm/session.py", line 2642, in _flush
    flush_context.execute()
  File "/home/sale/projects/coursework/iep_project/store_management_system/development/user_management_system/authentication_service/venv/lib/python3.10/site-packages/sqlalchemy/orm/unitofwork.py", line 422, in execute
    rec.execute(self)
  File "/home/sale/projects/coursework/iep_project/store_management_system/development/user_management_system/authentication_service/venv/lib/python3.10/site-packages/sqlalchemy/orm/unitofwork.py", line 586, in execute
    persistence.save_obj(
  File "/home/sale/projects/coursework/iep_project/store_management_system/development/user_management_system/authentication_service/venv/lib/python3.10/site-packages/sqlalchemy/orm/persistence.py", line 239, in save_obj
    _emit_insert_statements(
  File "/home/sale/projects/coursework/iep_project/store_management_system/development/user_management_system/authentication_service/venv/lib/python3.10/site-packages/sqlalchemy/orm/persistence.py", line 1135, in _emit_insert_statements
    result = cached_connections[connection].execute(
  File "/home/sale/projects/coursework/iep_project/store_management_system/development/user_management_system/authentication_service/venv/lib/python3.10/site-packages/sqlalchemy/engine/base.py", line 1011, in execute
    return meth(self, multiparams, params)
  File "/home/sale/projects/coursework/iep_project/store_management_system/development/user_management_system/authentication_service/venv/lib/python3.10/site-packages/sqlalchemy/sql/elements.py", line 298, in _execute_on_connection
    return connection._execute_clauseelement(self, multiparams, params)
  File "/home/sale/projects/coursework/iep_project/store_management_system/development/user_management_system/authentication_service/venv/lib/python3.10/site-packages/sqlalchemy/engine/base.py", line 1124, in _execute_clauseelement
    ret = self._execute_context(
  File "/home/sale/projects/coursework/iep_project/store_management_system/development/user_management_system/authentication_service/venv/lib/python3.10/site-packages/sqlalchemy/engine/base.py", line 1316, in _execute_context
    self._handle_dbapi_exception(
  File "/home/sale/projects/coursework/iep_project/store_management_system/development/user_management_system/authentication_service/venv/lib/python3.10/site-packages/sqlalchemy/engine/base.py", line 1510, in _handle_dbapi_exception
    util.raise_(
  File "/home/sale/projects/coursework/iep_project/store_management_system/development/user_management_system/authentication_service/venv/lib/python3.10/site-packages/sqlalchemy/util/compat.py", line 182, in raise_
    raise exception
  File "/home/sale/projects/coursework/iep_project/store_management_system/development/user_management_system/authentication_service/venv/lib/python3.10/site-packages/sqlalchemy/engine/base.py", line 1276, in _execute_context
    self.dialect.do_execute(
  File "/home/sale/projects/coursework/iep_project/store_management_system/development/user_management_system/authentication_service/venv/lib/python3.10/site-packages/sqlalchemy/engine/default.py", line 608, in do_execute
    cursor.execute(statement, parameters)
  File "/home/sale/projects/coursework/iep_project/store_management_system/development/user_management_system/authentication_service/venv/lib/python3.10/site-packages/pymysql/cursors.py", line 153, in execute
    result = self._query(query)
  File "/home/sale/projects/coursework/iep_project/store_management_system/development/user_management_system/authentication_service/venv/lib/python3.10/site-packages/pymysql/cursors.py", line 322, in _query
    conn.query(q)
  File "/home/sale/projects/coursework/iep_project/store_management_system/development/user_management_system/authentication_service/venv/lib/python3.10/site-packages/pymysql/connections.py", line 558, in query
    self._affected_rows = self._read_query_result(unbuffered=unbuffered)
  File "/home/sale/projects/coursework/iep_project/store_management_system/development/user_management_system/authentication_service/venv/lib/python3.10/site-packages/pymysql/connections.py", line 822, in _read_query_result
    result.read()
  File "/home/sale/projects/coursework/iep_project/store_management_system/development/user_management_system/authentication_service/venv/lib/python3.10/site-packages/pymysql/connections.py", line 1200, in read
    first_packet = self.connection._read_packet()
  File "/home/sale/projects/coursework/iep_project/store_management_system/development/user_management_system/authentication_service/venv/lib/python3.10/site-packages/pymysql/connections.py", line 772, in _read_packet
    packet.raise_for_error()
  File "/home/sale/projects/coursework/iep_project/store_management_system/development/user_management_system/authentication_service/venv/lib/python3.10/site-packages/pymysql/protocol.py", line 221, in raise_for_error
    err.raise_mysql_exception(self._data)
  File "/home/sale/projects/coursework/iep_project/store_management_system/development/user_management_system/authentication_service/venv/lib/python3.10/site-packages/pymysql/err.py", line 143, in raise_mysql_exception
    raise errorclass(errno, errval)
sqlalchemy.exc.OperationalError: (pymysql.err.OperationalError) (1049, "Unknown database 'authentication'")
[SQL: INSERT INTO users (email, forename, surname, password) VALUES (%(email)s, %(forename)s, %(surname)s, %(password)s)]
[parameters: {'email': 'jane@gmail.com', 'forename': 'Jane', 'surname': 'Doe', 'password': 'aA123456'}]
(Background on this error at: http://sqlalche.me/e/13/e3q8)
2023-08-29 14:13:00 [ERROR] Failed to login
Traceback (most recent call last):
  File "/home/sale/projects/coursework/iep_project/store_management_system/development/user_management_system/authentication_service/venv/lib/python3.10/site-packages/sqlalchemy/engine/base.py", line 1276, in _execute_context
    self.dialect.do_execute(
  File "/home/sale/projects/coursework/iep_project/store_management_system/development/user_management_system/authentication_service/venv/lib/python3.10/site-packages/sqlalchemy/engine/default.py", line 608, in do_execute
    cursor.execute(statement, parameters)
  File "/home/sale/projects/coursework/iep_project/store_management_system/development/user_management_system/authentication_service/venv/lib/python3.10/site-packages/pymysql/cursors.py", line 153, in execute
    result = self._query(query)
  File "/home/sale/projects/coursework/iep_project/store_management_system/development/user_management_system/authentication_service/venv/lib/python3.10/site-packages/pymysql/cursors.py", line 322, in _query
    conn.query(q)
  File "/home/sale/projects/coursework/iep_project/store_management_system/development/user_management_system/authentication_service/venv/lib/python3.10/site-packages/pymysql/connections.py", line 558, in query
    self._affected_rows = self._read_query_result(unbuffered=unbuffered)
  File "/home/sale/projects/coursework/iep_project/store_management_system/development/user_management_system/authentication_service/venv/lib/python3.10/site-packages/pymysql/connections.py", line 822, in _read_query_result
    result.read()
  File "/home/sale/projects/coursework/iep_project/store_management_system/development/user_management_system/authentication_service/venv/lib/python3.10/site-packages/pymysql/connections.py", line 1200, in read
    first_packet = self.connection._read_packet()
  File "/home/sale/projects/coursework/iep_project/store_management_system/development/user_management_system/authentication_service/venv/lib/python3.10/site-packages/pymysql/connections.py", line 772, in _read_packet
    packet.raise_for_error()
  File "/home/sale/projects/coursework/iep_project/store_management_system/development/user_management_system/authentication_service/venv/lib/python3.10/site-packages/pymysql/protocol.py", line 221, in raise_for_error
    err.raise_mysql_exception(self._data)
  File "/home/sale/projects/coursework/iep_project/store_management_system/development/user_management_system/authentication_service/venv/lib/python3.10/site-packages/pymysql/err.py", line 143, in raise_mysql_exception
    raise errorclass(errno, errval)
pymysql.err.OperationalError: (1049, "Unknown database 'authentication'")

The above exception was the direct cause of the following exception:

Traceback (most recent call last):
  File "/home/sale/projects/coursework/iep_project/store_management_system/development/user_management_system/authentication_service/app/blueprints/login.py", line 78, in login_user
    ).first()
  File "/home/sale/projects/coursework/iep_project/store_management_system/development/user_management_system/authentication_service/venv/lib/python3.10/site-packages/sqlalchemy/orm/query.py", line 3429, in first
    ret = list(self[0:1])
  File "/home/sale/projects/coursework/iep_project/store_management_system/development/user_management_system/authentication_service/venv/lib/python3.10/site-packages/sqlalchemy/orm/query.py", line 3203, in __getitem__
    return list(res)
  File "/home/sale/projects/coursework/iep_project/store_management_system/development/user_management_system/authentication_service/venv/lib/python3.10/site-packages/sqlalchemy/orm/query.py", line 3535, in __iter__
    return self._execute_and_instances(context)
  File "/home/sale/projects/coursework/iep_project/store_management_system/development/user_management_system/authentication_service/venv/lib/python3.10/site-packages/sqlalchemy/orm/query.py", line 3560, in _execute_and_instances
    result = conn.execute(querycontext.statement, self._params)
  File "/home/sale/projects/coursework/iep_project/store_management_system/development/user_management_system/authentication_service/venv/lib/python3.10/site-packages/sqlalchemy/engine/base.py", line 1011, in execute
    return meth(self, multiparams, params)
  File "/home/sale/projects/coursework/iep_project/store_management_system/development/user_management_system/authentication_service/venv/lib/python3.10/site-packages/sqlalchemy/sql/elements.py", line 298, in _execute_on_connection
    return connection._execute_clauseelement(self, multiparams, params)
  File "/home/sale/projects/coursework/iep_project/store_management_system/development/user_management_system/authentication_service/venv/lib/python3.10/site-packages/sqlalchemy/engine/base.py", line 1124, in _execute_clauseelement
    ret = self._execute_context(
  File "/home/sale/projects/coursework/iep_project/store_management_system/development/user_management_system/authentication_service/venv/lib/python3.10/site-packages/sqlalchemy/engine/base.py", line 1316, in _execute_context
    self._handle_dbapi_exception(
  File "/home/sale/projects/coursework/iep_project/store_management_system/development/user_management_system/authentication_service/venv/lib/python3.10/site-packages/sqlalchemy/engine/base.py", line 1510, in _handle_dbapi_exception
    util.raise_(
  File "/home/sale/projects/coursework/iep_project/store_management_system/development/user_management_system/authentication_service/venv/lib/python3.10/site-packages/sqlalchemy/util/compat.py", line 182, in raise_
    raise exception
  File "/home/sale/projects/coursework/iep_project/store_management_system/development/user_management_system/authentication_service/venv/lib/python3.10/site-packages/sqlalchemy/engine/base.py", line 1276, in _execute_context
    self.dialect.do_execute(
  File "/home/sale/projects/coursework/iep_project/store_management_system/development/user_management_system/authentication_service/venv/lib/python3.10/site-packages/sqlalchemy/engine/default.py", line 608, in do_execute
    cursor.execute(statement, parameters)
  File "/home/sale/projects/coursework/iep_project/store_management_system/development/user_management_system/authentication_service/venv/lib/python3.10/site-packages/pymysql/cursors.py", line 153, in execute
    result = self._query(query)
  File "/home/sale/projects/coursework/iep_project/store_management_system/development/user_management_system/authentication_service/venv/lib/python3.10/site-packages/pymysql/cursors.py", line 322, in _query
    conn.query(q)
  File "/home/sale/projects/coursework/iep_project/store_management_system/development/user_management_system/authentication_service/venv/lib/python3.10/site-packages/pymysql/connections.py", line 558, in query
    self._affected_rows = self._read_query_result(unbuffered=unbuffered)
  File "/home/sale/projects/coursework/iep_project/store_management_system/development/user_management_system/authentication_service/venv/lib/python3.10/site-packages/pymysql/connections.py", line 822, in _read_query_result
    result.read()
  File "/home/sale/projects/coursework/iep_project/store_management_system/development/user_management_system/authentication_service/venv/lib/python3.10/site-packages/pymysql/connections.py", line 1200, in read
    first_packet = self.connection._read_packet()
  File "/home/sale/projects/coursework/iep_project/store_management_system/development/user_management_system/authentication_service/venv/lib/python3.10/site-packages/pymysql/connections.py", line 772, in _read_packet
    packet.raise_for_error()
  File "/home/sale/projects/coursework/iep_project/store_management_system/development/user_management_system/authentication_service/venv/lib/python3.10/site-packages/pymysql/protocol.py", line 221, in raise_for_error
    err.raise_mysql_exception(self._data)
  File "/home/sale/projects/coursework/iep_project/store_management_system/development/user_management_system/authentication_service/venv/lib/python3.10/site-packages/pymysql/err.py", line 143, in raise_mysql_exception
    raise errorclass(errno, errval)
sqlalchemy.exc.OperationalError: (pymysql.err.OperationalError) (1049, "Unknown database 'authentication'")
[SQL: SELECT users.id AS users_id, users.email AS users_email, users.forename AS users_forename, users.surname AS users_surname, users.password AS users_password 
FROM users 
WHERE users.email = %(email_1)s AND users.password = %(password_1)s 
 LIMIT %(param_1)s]
[parameters: {'email_1': 'jane@gmail.com', 'password_1': 'aA123456', 'param_1': 1}]
(Background on this error at: http://sqlalche.me/e/13/e3q8)
2023-08-29 14:13:00 [ERROR] Failed to login
Traceback (most recent call last):
  File "/home/sale/projects/coursework/iep_project/store_management_system/development/user_management_system/authentication_service/venv/lib/python3.10/site-packages/sqlalchemy/engine/base.py", line 1276, in _execute_context
    self.dialect.do_execute(
  File "/home/sale/projects/coursework/iep_project/store_management_system/development/user_management_system/authentication_service/venv/lib/python3.10/site-packages/sqlalchemy/engine/default.py", line 608, in do_execute
    cursor.execute(statement, parameters)
  File "/home/sale/projects/coursework/iep_project/store_management_system/development/user_management_system/authentication_service/venv/lib/python3.10/site-packages/pymysql/cursors.py", line 153, in execute
    result = self._query(query)
  File "/home/sale/projects/coursework/iep_project/store_management_system/development/user_management_system/authentication_service/venv/lib/python3.10/site-packages/pymysql/cursors.py", line 322, in _query
    conn.query(q)
  File "/home/sale/projects/coursework/iep_project/store_management_system/development/user_management_system/authentication_service/venv/lib/python3.10/site-packages/pymysql/connections.py", line 558, in query
    self._affected_rows = self._read_query_result(unbuffered=unbuffered)
  File "/home/sale/projects/coursework/iep_project/store_management_system/development/user_management_system/authentication_service/venv/lib/python3.10/site-packages/pymysql/connections.py", line 822, in _read_query_result
    result.read()
  File "/home/sale/projects/coursework/iep_project/store_management_system/development/user_management_system/authentication_service/venv/lib/python3.10/site-packages/pymysql/connections.py", line 1200, in read
    first_packet = self.connection._read_packet()
  File "/home/sale/projects/coursework/iep_project/store_management_system/development/user_management_system/authentication_service/venv/lib/python3.10/site-packages/pymysql/connections.py", line 772, in _read_packet
    packet.raise_for_error()
  File "/home/sale/projects/coursework/iep_project/store_management_system/development/user_management_system/authentication_service/venv/lib/python3.10/site-packages/pymysql/protocol.py", line 221, in raise_for_error
    err.raise_mysql_exception(self._data)
  File "/home/sale/projects/coursework/iep_project/store_management_system/development/user_management_system/authentication_service/venv/lib/python3.10/site-packages/pymysql/err.py", line 143, in raise_mysql_exception
    raise errorclass(errno, errval)
pymysql.err.OperationalError: (1049, "Unknown database 'authentication'")

The above exception was the direct cause of the following exception:

Traceback (most recent call last):
  File "/home/sale/projects/coursework/iep_project/store_management_system/development/user_management_system/authentication_service/app/blueprints/login.py", line 78, in login_user
    ).first()
  File "/home/sale/projects/coursework/iep_project/store_management_system/development/user_management_system/authentication_service/venv/lib/python3.10/site-packages/sqlalchemy/orm/query.py", line 3429, in first
    ret = list(self[0:1])
  File "/home/sale/projects/coursework/iep_project/store_management_system/development/user_management_system/authentication_service/venv/lib/python3.10/site-packages/sqlalchemy/orm/query.py", line 3203, in __getitem__
    return list(res)
  File "/home/sale/projects/coursework/iep_project/store_management_system/development/user_management_system/authentication_service/venv/lib/python3.10/site-packages/sqlalchemy/orm/query.py", line 3535, in __iter__
    return self._execute_and_instances(context)
  File "/home/sale/projects/coursework/iep_project/store_management_system/development/user_management_system/authentication_service/venv/lib/python3.10/site-packages/sqlalchemy/orm/query.py", line 3560, in _execute_and_instances
    result = conn.execute(querycontext.statement, self._params)
  File "/home/sale/projects/coursework/iep_project/store_management_system/development/user_management_system/authentication_service/venv/lib/python3.10/site-packages/sqlalchemy/engine/base.py", line 1011, in execute
    return meth(self, multiparams, params)
  File "/home/sale/projects/coursework/iep_project/store_management_system/development/user_management_system/authentication_service/venv/lib/python3.10/site-packages/sqlalchemy/sql/elements.py", line 298, in _execute_on_connection
    return connection._execute_clauseelement(self, multiparams, params)
  File "/home/sale/projects/coursework/iep_project/store_management_system/development/user_management_system/authentication_service/venv/lib/python3.10/site-packages/sqlalchemy/engine/base.py", line 1124, in _execute_clauseelement
    ret = self._execute_context(
  File "/home/sale/projects/coursework/iep_project/store_management_system/development/user_management_system/authentication_service/venv/lib/python3.10/site-packages/sqlalchemy/engine/base.py", line 1316, in _execute_context
    self._handle_dbapi_exception(
  File "/home/sale/projects/coursework/iep_project/store_management_system/development/user_management_system/authentication_service/venv/lib/python3.10/site-packages/sqlalchemy/engine/base.py", line 1510, in _handle_dbapi_exception
    util.raise_(
  File "/home/sale/projects/coursework/iep_project/store_management_system/development/user_management_system/authentication_service/venv/lib/python3.10/site-packages/sqlalchemy/util/compat.py", line 182, in raise_
    raise exception
  File "/home/sale/projects/coursework/iep_project/store_management_system/development/user_management_system/authentication_service/venv/lib/python3.10/site-packages/sqlalchemy/engine/base.py", line 1276, in _execute_context
    self.dialect.do_execute(
  File "/home/sale/projects/coursework/iep_project/store_management_system/development/user_management_system/authentication_service/venv/lib/python3.10/site-packages/sqlalchemy/engine/default.py", line 608, in do_execute
    cursor.execute(statement, parameters)
  File "/home/sale/projects/coursework/iep_project/store_management_system/development/user_management_system/authentication_service/venv/lib/python3.10/site-packages/pymysql/cursors.py", line 153, in execute
    result = self._query(query)
  File "/home/sale/projects/coursework/iep_project/store_management_system/development/user_management_system/authentication_service/venv/lib/python3.10/site-packages/pymysql/cursors.py", line 322, in _query
    conn.query(q)
  File "/home/sale/projects/coursework/iep_project/store_management_system/development/user_management_system/authentication_service/venv/lib/python3.10/site-packages/pymysql/connections.py", line 558, in query
    self._affected_rows = self._read_query_result(unbuffered=unbuffered)
  File "/home/sale/projects/coursework/iep_project/store_management_system/development/user_management_system/authentication_service/venv/lib/python3.10/site-packages/pymysql/connections.py", line 822, in _read_query_result
    result.read()
  File "/home/sale/projects/coursework/iep_project/store_management_system/development/user_management_system/authentication_service/venv/lib/python3.10/site-packages/pymysql/connections.py", line 1200, in read
    first_packet = self.connection._read_packet()
  File "/home/sale/projects/coursework/iep_project/store_management_system/development/user_management_system/authentication_service/venv/lib/python3.10/site-packages/pymysql/connections.py", line 772, in _read_packet
    packet.raise_for_error()
  File "/home/sale/projects/coursework/iep_project/store_management_system/development/user_management_system/authentication_service/venv/lib/python3.10/site-packages/pymysql/protocol.py", line 221, in raise_for_error
    err.raise_mysql_exception(self._data)
  File "/home/sale/projects/coursework/iep_project/store_management_system/development/user_management_system/authentication_service/venv/lib/python3.10/site-packages/pymysql/err.py", line 143, in raise_mysql_exception
    raise errorclass(errno, errval)
sqlalchemy.exc.OperationalError: (pymysql.err.OperationalError) (1049, "Unknown database 'authentication'")
[SQL: SELECT users.id AS users_id, users.email AS users_email, users.forename AS users_forename, users.surname AS users_surname, users.password AS users_password 
FROM users 
WHERE users.email = %(email_1)s AND users.password = %(password_1)s 
 LIMIT %(param_1)s]
[parameters: {'email_1': 'jane@gmail.com', 'password_1': 'aA123456', 'param_1': 1}]
(Background on this error at: http://sqlalche.me/e/13/e3q8)
2023-08-29 14:13:00 [ERROR] Failed to login
Traceback (most recent call last):
  File "/home/sale/projects/coursework/iep_project/store_management_system/development/user_management_system/authentication_service/venv/lib/python3.10/site-packages/sqlalchemy/engine/base.py", line 1276, in _execute_context
    self.dialect.do_execute(
  File "/home/sale/projects/coursework/iep_project/store_management_system/development/user_management_system/authentication_service/venv/lib/python3.10/site-packages/sqlalchemy/engine/default.py", line 608, in do_execute
    cursor.execute(statement, parameters)
  File "/home/sale/projects/coursework/iep_project/store_management_system/development/user_management_system/authentication_service/venv/lib/python3.10/site-packages/pymysql/cursors.py", line 153, in execute
    result = self._query(query)
  File "/home/sale/projects/coursework/iep_project/store_management_system/development/user_management_system/authentication_service/venv/lib/python3.10/site-packages/pymysql/cursors.py", line 322, in _query
    conn.query(q)
  File "/home/sale/projects/coursework/iep_project/store_management_system/development/user_management_system/authentication_service/venv/lib/python3.10/site-packages/pymysql/connections.py", line 558, in query
    self._affected_rows = self._read_query_result(unbuffered=unbuffered)
  File "/home/sale/projects/coursework/iep_project/store_management_system/development/user_management_system/authentication_service/venv/lib/python3.10/site-packages/pymysql/connections.py", line 822, in _read_query_result
    result.read()
  File "/home/sale/projects/coursework/iep_project/store_management_system/development/user_management_system/authentication_service/venv/lib/python3.10/site-packages/pymysql/connections.py", line 1200, in read
    first_packet = self.connection._read_packet()
  File "/home/sale/projects/coursework/iep_project/store_management_system/development/user_management_system/authentication_service/venv/lib/python3.10/site-packages/pymysql/connections.py", line 772, in _read_packet
    packet.raise_for_error()
  File "/home/sale/projects/coursework/iep_project/store_management_system/development/user_management_system/authentication_service/venv/lib/python3.10/site-packages/pymysql/protocol.py", line 221, in raise_for_error
    err.raise_mysql_exception(self._data)
  File "/home/sale/projects/coursework/iep_project/store_management_system/development/user_management_system/authentication_service/venv/lib/python3.10/site-packages/pymysql/err.py", line 143, in raise_mysql_exception
    raise errorclass(errno, errval)
pymysql.err.OperationalError: (1049, "Unknown database 'authentication'")

The above exception was the direct cause of the following exception:

Traceback (most recent call last):
  File "/home/sale/projects/coursework/iep_project/store_management_system/development/user_management_system/authentication_service/app/blueprints/login.py", line 78, in login_user
    ).first()
  File "/home/sale/projects/coursework/iep_project/store_management_system/development/user_management_system/authentication_service/venv/lib/python3.10/site-packages/sqlalchemy/orm/query.py", line 3429, in first
    ret = list(self[0:1])
  File "/home/sale/projects/coursework/iep_project/store_management_system/development/user_management_system/authentication_service/venv/lib/python3.10/site-packages/sqlalchemy/orm/query.py", line 3203, in __getitem__
    return list(res)
  File "/home/sale/projects/coursework/iep_project/store_management_system/development/user_management_system/authentication_service/venv/lib/python3.10/site-packages/sqlalchemy/orm/query.py", line 3535, in __iter__
    return self._execute_and_instances(context)
  File "/home/sale/projects/coursework/iep_project/store_management_system/development/user_management_system/authentication_service/venv/lib/python3.10/site-packages/sqlalchemy/orm/query.py", line 3560, in _execute_and_instances
    result = conn.execute(querycontext.statement, self._params)
  File "/home/sale/projects/coursework/iep_project/store_management_system/development/user_management_system/authentication_service/venv/lib/python3.10/site-packages/sqlalchemy/engine/base.py", line 1011, in execute
    return meth(self, multiparams, params)
  File "/home/sale/projects/coursework/iep_project/store_management_system/development/user_management_system/authentication_service/venv/lib/python3.10/site-packages/sqlalchemy/sql/elements.py", line 298, in _execute_on_connection
    return connection._execute_clauseelement(self, multiparams, params)
  File "/home/sale/projects/coursework/iep_project/store_management_system/development/user_management_system/authentication_service/venv/lib/python3.10/site-packages/sqlalchemy/engine/base.py", line 1124, in _execute_clauseelement
    ret = self._execute_context(
  File "/home/sale/projects/coursework/iep_project/store_management_system/development/user_management_system/authentication_service/venv/lib/python3.10/site-packages/sqlalchemy/engine/base.py", line 1316, in _execute_context
    self._handle_dbapi_exception(
  File "/home/sale/projects/coursework/iep_project/store_management_system/development/user_management_system/authentication_service/venv/lib/python3.10/site-packages/sqlalchemy/engine/base.py", line 1510, in _handle_dbapi_exception
    util.raise_(
  File "/home/sale/projects/coursework/iep_project/store_management_system/development/user_management_system/authentication_service/venv/lib/python3.10/site-packages/sqlalchemy/util/compat.py", line 182, in raise_
    raise exception
  File "/home/sale/projects/coursework/iep_project/store_management_system/development/user_management_system/authentication_service/venv/lib/python3.10/site-packages/sqlalchemy/engine/base.py", line 1276, in _execute_context
    self.dialect.do_execute(
  File "/home/sale/projects/coursework/iep_project/store_management_system/development/user_management_system/authentication_service/venv/lib/python3.10/site-packages/sqlalchemy/engine/default.py", line 608, in do_execute
    cursor.execute(statement, parameters)
  File "/home/sale/projects/coursework/iep_project/store_management_system/development/user_management_system/authentication_service/venv/lib/python3.10/site-packages/pymysql/cursors.py", line 153, in execute
    result = self._query(query)
  File "/home/sale/projects/coursework/iep_project/store_management_system/development/user_management_system/authentication_service/venv/lib/python3.10/site-packages/pymysql/cursors.py", line 322, in _query
    conn.query(q)
  File "/home/sale/projects/coursework/iep_project/store_management_system/development/user_management_system/authentication_service/venv/lib/python3.10/site-packages/pymysql/connections.py", line 558, in query
    self._affected_rows = self._read_query_result(unbuffered=unbuffered)
  File "/home/sale/projects/coursework/iep_project/store_management_system/development/user_management_system/authentication_service/venv/lib/python3.10/site-packages/pymysql/connections.py", line 822, in _read_query_result
    result.read()
  File "/home/sale/projects/coursework/iep_project/store_management_system/development/user_management_system/authentication_service/venv/lib/python3.10/site-packages/pymysql/connections.py", line 1200, in read
    first_packet = self.connection._read_packet()
  File "/home/sale/projects/coursework/iep_project/store_management_system/development/user_management_system/authentication_service/venv/lib/python3.10/site-packages/pymysql/connections.py", line 772, in _read_packet
    packet.raise_for_error()
  File "/home/sale/projects/coursework/iep_project/store_management_system/development/user_management_system/authentication_service/venv/lib/python3.10/site-packages/pymysql/protocol.py", line 221, in raise_for_error
    err.raise_mysql_exception(self._data)
  File "/home/sale/projects/coursework/iep_project/store_management_system/development/user_management_system/authentication_service/venv/lib/python3.10/site-packages/pymysql/err.py", line 143, in raise_mysql_exception
    raise errorclass(errno, errval)
sqlalchemy.exc.OperationalError: (pymysql.err.OperationalError) (1049, "Unknown database 'authentication'")
[SQL: SELECT users.id AS users_id, users.email AS users_email, users.forename AS users_forename, users.surname AS users_surname, users.password AS users_password 
FROM users 
WHERE users.email = %(email_1)s AND users.password = %(password_1)s 
 LIMIT %(param_1)s]
[parameters: {'email_1': 'john@gmail.com', 'password_1': 'aA123456', 'param_1': 1}]
(Background on this error at: http://sqlalche.me/e/13/e3q8)
2023-08-29 14:14:54 [INFO] Configured app logging, linked to file:
./logs/log1.log

2023-08-29 14:14:55 [INFO] Configured app logging, linked to file:
./logs/log1.log

2023-08-29 15:03:17 [INFO] Configured app logging, linked to file:
./logs/log1.log

2023-08-29 15:03:17 [INFO] Configured app logging, linked to file:
./logs/log1.log

